Workbook

Sheet Resumo_Analise
A1: 📊 RESUMO ANALÍTICO - VÁLVULAS DIAFRAGMA
A3: 🔧 FERMENTADORES (FTD01-FTD12) | E3: 🧪 PROPAGADORES (PGD01-PGD12) | I3: ⚙️ BLENDERS (BLD01-BLD02)
A5: Equipamento | B5: GEMÜ | C5: ZDL | E5: Equipamento | F5: GEMÜ | G5: ZDL | I5: Equipamento | J5: GEMÜ | K5: ZDL
A6: FTD01 | B6: =COUNTIF('FTD01'!G:G,"GEMÜ") -> 35 | C6: =COUNTIF('FTD01'!G:G,"ZDL") -> 7 | E6: PGD01 | F6: =COUNTIF('PGD01'!G:G,"GEMÜ") -> 32 | G6: =COUNTIF('PGD01'!G:G,"ZDL") -> 6 | I6: BLD01 | J6: =COUNTIF('BLD02'!G:G,"GEMÜ") -> 22 | K6: =COUNTIF('BLD02'!G:G,"ZDL") -> 8
A7: FTD02 | B7: =COUNTIF('FTD02'!G:G,"GEMÜ") -> 35 | C7: =COUNTIF('FTD02'!G:G,"ZDL") -> 7 | E7: PGD02 | F7: =COUNTIF('PGD02'!G:G,"GEMÜ") -> 34 | G7: =COUNTIF('PGD02'!G:G,"ZDL") -> 4 | I7: BLD02 | J7: 22 | K7: 8
A8: FTD03 | B8: =COUNTIF('FTD03'!G:G,"GEMÜ") -> 35 | C8: =COUNTIF('FTD03'!G:G,"ZDL") -> 7 | E8: PGD03 | F8: =COUNTIF('PGD03'!G:G,"GEMÜ") -> 33 | G8: =COUNTIF('PGD03'!G:G,"ZDL") -> 5 | I8: TOTAL BLD | J8: =SUM(J6:J7) -> 44 | K8: =SUM(K6:K7) -> 16
A9: FTD04 | B9: =COUNTIF('FTD04'!G:G,"GEMÜ") -> 35 | C9: =COUNTIF('FTD04'!G:G,"ZDL") -> 7 | E9: PGD04 | F9: =COUNTIF('PGD04'!G:G,"GEMÜ") -> 33 | G9: =COUNTIF('PGD04'!G:G,"ZDL") -> 5
A10: FTD05 | B10: =COUNTIF('FTD05'!G:G,"GEMÜ") -> 34 | C10: =COUNTIF('FTD05'!G:G,"ZDL") -> 8 | E10: PGD05 | F10: =COUNTIF('PGD05'!G:G,"GEMÜ") -> 33 | G10: =COUNTIF('PGD05'!G:G,"ZDL") -> 5
A11: FTD06 | B11: =COUNTIF('FTD06'!G:G,"GEMÜ") -> 36 | C11: =COUNTIF('FTD06'!G:G,"ZDL") -> 6 | E11: PGD06 | F11: =COUNTIF('PGD06'!G:G,"GEMÜ") -> 33 | G11: =COUNTIF('PGD06'!G:G,"ZDL") -> 5
A12: FTD07 | B12: =COUNTIF('FTD07'!G:G,"GEMÜ") -> 36 | C12: =COUNTIF('FTD07'!G:G,"ZDL") -> 7 | E12: PGD07 | F12: =COUNTIF('PGD07'!G:G,"GEMÜ") -> 33 | G12: =COUNTIF('PGD07'!G:G,"ZDL") -> 5
A13: FTD08 | B13: =COUNTIF('FTD08'!G:G,"GEMÜ") -> 36 | C13: =COUNTIF('FTD08'!G:G,"ZDL") -> 6 | E13: PGD08 | F13: =COUNTIF('PGD08'!G:G,"GEMÜ") -> 32 | G13: =COUNTIF('PGD08'!G:G,"ZDL") -> 6
A14: FTD09 | B14: =COUNTIF('FTD09'!G:G,"GEMÜ") -> 34 | C14: =COUNTIF('FTD09'!G:G,"ZDL") -> 9 | E14: PGD09 | F14: =COUNTIF('PGD09'!G:G,"GEMÜ") -> 33 | G14: =COUNTIF('PGD09'!G:G,"ZDL") -> 5
A15: FTD10 | B15: =COUNTIF('FTD10'!G:G,"GEMÜ") -> 34 | C15: =COUNTIF('FTD10'!G:G,"ZDL") -> 9 | E15: PGD10 | F15: =COUNTIF('PGD10'!G:G,"GEMÜ") -> 33 | G15: =COUNTIF('PGD10'!G:G,"ZDL") -> 5
A16: FTD11 | B16: =COUNTIF('FTD11'!G:G,"GEMÜ") -> 35 | C16: =COUNTIF('FTD11'!G:G,"ZDL") -> 7 | E16: PGD11 | F16: =COUNTIF('PGD11'!G:G,"GEMÜ") -> 33 | G16: =COUNTIF('PGD11'!G:G,"ZDL") -> 5
A17: FTD12 | B17: =COUNTIF('FTD12'!G:G,"GEMÜ") -> 34 | C17: =COUNTIF('FTD12'!G:G,"ZDL") -> 0 | E17: PGD12 | F17: =COUNTIF('PGD12'!G:G,"GEMÜ") -> 33 | G17: =COUNTIF('PGD12'!G:G,"ZDL") -> 5
A18: TOTAL FTD | B18: =SUM(B6:B17) -> 419 | C18: =SUM(C6:C17) -> 80 | E18: TOTAL PGD | F18: =SUM(F6:F17) -> 395 | G18: =SUM(G6:G17) -> 61
A21: 📈 CONSOLIDADO GERAL
A23: Categoria | B23: GEMÜ | C23: ZDL
A24: Fermentadores (FTD) | B24: =B18 -> 419 | C24: =C18 -> 80
A25: Propagadores (PGD) | B25: =F18 -> 395 | C25: =G18 -> 61
A26: Blenders (BLD) | B26: =J8 -> 44 | C26: =K8 -> 16
A27: TOTAL GERAL | B27: =SUM(B24:B26) -> 858 | C27: =SUM(C24:C26) -> 157

Sheet Lista REV PGD
B2: FTD01 | E2: FTD02 | H2: FTD03 | K2: FTD04 | N2: FTD05 | Q2: FTD06 | T2: FTD07 | W2: FTD08 | Z2: FTD09 | AC2: FTD10 | AF2: FTD11 | AI2: FTD12 | AN2: PGD01 | AR2: PGD02 | AV2: PGD03 | AZ2: PGD04 | BD2: PGD05 | BH2: PGD06 | BL2: PGD07 | BP2: PGD08 | BT2: PGD09 | BX2: PGD10 | CB2: PGD11 | CF2: PGD12 | CL2: BLD01 | CO2: BLD02
B3: DESCRIÇÃO | C3: DN | D3: MARCA | E3: DESCRIÇÃO | F3: DN | G3: MARCA | H3: DESCRIÇÃO | I3: DN | J3: MARCA | K3: DESCRIÇÃO | L3: DN | M3: MARCA | N3: DESCRIÇÃO | O3: DN | P3: MARCA | Q3: DESCRIÇÃO | R3: DN | S3: MARCA | T3: DESCRIÇÃO | U3: DN | V3: MARCA | W3: DESCRIÇÃO | X3: DN | Y3: MARCA | Z3: DESCRIÇÃO | AA3: DN | AB3: MARCA | AC3: DESCRIÇÃO | AD3: DN | AE3: MARCA | AF3: DESCRIÇÃO | AG3: DN | AH3: MARCA | AI3: DESCRIÇÃO | AJ3: DN | AK3: MARCA | AN3: LOCAL | AO3: DESCRIÇÃO | AP3: DN | AQ3: TAG | AR3: LOCAL | AS3: DESCRIÇÃO | AT3: DN | AU3: MARCA | AV3: LOCAL | AW3: DESCRIÇÃO | AX3: DN | AY3: MARCA | AZ3: LOCAL | BA3: DESCRIÇÃO | BB3: DN | BC3: MARCA | BD3: LOCAL | BE3: DESCRIÇÃO | BF3: DN | BG3: MARCA | BH3: LOCAL | BI3: DESCRIÇÃO | BJ3: DN | BK3: MARCA | BL3: LOCAL | BM3: DESCRIÇÃO | BN3: DN | BO3: MARCA | BP3: LOCAL | BQ3: DESCRIÇÃO | BR3: DN | BS3: MARCA | BT3: LOCAL | BU3: DESCRIÇÃO | BV3: DN | BW3: MARCA | BX3: LOCAL | BY3: DESCRIÇÃO | BZ3: DN | CA3: MARCA | CB3: LOCAL | CC3: DESCRIÇÃO | CD3: DN | CE3: MARCA | CF3: LOCAL | CG3: DESCRIÇÃO | CH3: DN | CI3: MARCA | CL3: DESCRIÇÃO | CM3: DN | CN3: MARCA | CO3: DESCRIÇÃO | CP3: DN | CQ3: MARCA
B4: Alimentação de vapor fundo do tanque e bloco de amostra | C4: DN-8 | D4: ZDL | E4: =VLOOKUP(B4,'FTD02'!C:E,1,0) -> Alimentação de vapor fundo do tanque e bloco de amostra | F4: =VLOOKUP(B4,'FTD02'!C:E,3,0) -> DN-8 | G4: =VLOOKUP(B4,'FTD02'!C:G,5,0) -> ZDL | H4: =VLOOKUP(B4,'FTD03'!C:E,1,0) -> Alimentação de vapor fundo do tanque e bloco de amostra | I4: =VLOOKUP(B4,'FTD03'!C:E,3,0) -> DN-8 | J4: =VLOOKUP(B4,'FTD03'!C:G,5,0) -> ZDL | K4: =VLOOKUP(B4,'FTD04'!C:E,1,0) -> Alimentação de vapor fundo do tanque e bloco de amostra | L4: =VLOOKUP(B4,'FTD04'!C:E,3,0) -> DN-8 | M4: =VLOOKUP(B4,'FTD04'!C:G,5,0) -> GEMÜ | N4: =VLOOKUP(B4,'FTD05'!C:E,1,0) -> Alimentação de vapor fundo do tanque e bloco de amostra | O4: =VLOOKUP(B4,'FTD05'!C:E,3,0) -> DN-8 | P4: =VLOOKUP(B4,'FTD05'!C:G,5,0) -> ZDL | Q4: =VLOOKUP(B4,'FTD06'!C:E,1,0) -> Alimentação de vapor fundo do tanque e bloco de amostra | R4: =VLOOKUP(B4,'FTD06'!C:E,3,0) -> DN-8 | S4: =VLOOKUP(B4,'FTD06'!C:G,5,0) -> ZDL | T4: =VLOOKUP(B4,'FTD07'!C:E,1,0) -> Alimentação de vapor fundo do tanque e bloco de amostra | U4: =VLOOKUP(B4,'FTD07'!C:E,3,0) -> DN-8 | V4: =VLOOKUP(B4,'FTD07'!C:G,5,0) -> GEMÜ | W4: =VLOOKUP(B4,'FTD08'!C:E,1,0) -> Alimentação de vapor fundo do tanque e bloco de amostra | X4: =VLOOKUP(B4,'FTD08'!C:E,3,0) -> DN-8 | Y4: =VLOOKUP(B4,'FTD08'!C:G,5,0) -> GEMÜ | Z4: =VLOOKUP(B4,'FTD09'!C:E,1,0) -> Alimentação de vapor fundo do tanque e bloco de amostra | AA4: =VLOOKUP(B4,'FTD09'!C:E,3,0) -> DN-8 | AB4: =VLOOKUP(B4,'FTD09'!C:G,5,0) -> ZDL | AC4: =VLOOKUP(B4,'FTD10'!C:E,1,0) -> Alimentação de vapor fundo do tanque e bloco de amostra | AD4: =VLOOKUP(B4,'FTD10'!C:E,3,0) -> DN-8 | AE4: =VLOOKUP(B4,'FTD10'!C:G,5,0) -> GEMÜ | AF4: =VLOOKUP(B4,'FTD11'!C:E,1,0) -> Alimentação de vapor fundo do tanque e bloco de amostra | AG4: =VLOOKUP(B4,'FTD11'!C:E,3,0) -> DN-8 | AH4: =VLOOKUP(B4,'FTD11'!C:G,5,0) -> GEMÜ | AI4: =VLOOKUP(B4,'FTD12'!C:E,1,0) -> Alimentação de vapor fundo do tanque e bloco de amostra | AJ4: =VLOOKUP(B4,'FTD12'!C:E,3,0) -> DN-8 | AK4: =VLOOKUP(B4,'FTD12'!C:G,5,0) -> ZDL | AL4: =COUNTIF(E4:AJ4,AJ4) -> 11 | AN4: Inferior | AO4: Bloco 2 vias fundo – Vapor | AP4: DN-40 | AQ4: BV-09.22 | AR4: =VLOOKUP(AN4,'PGD02'!A:E,1,0) -> Inferior | AS4: =VLOOKUP(AO4,'PGD02'!C:E,1,0) -> Bloco 2 vias fundo – Vapor | AT4: =VLOOKUP(AO4,'PGD02'!C:E,3,0) -> DN-40 | AU4: =VLOOKUP(AO4,'PGD02'!C:G,5,0) -> GEMÜ | AV4: =VLOOKUP(AN4,'PGD03'!A:E,1,0) -> Inferior | AW4: =VLOOKUP(AO4,'PGD03'!C:E,1,0) -> Bloco 2 vias fundo – Vapor | AX4: =VLOOKUP(AO4,'PGD03'!C:E,3,0) -> DN-40 | AY4: =VLOOKUP(AO4,'PGD03'!C:G,5,0) -> GEMÜ | AZ4: =VLOOKUP(AN4,'PGD04'!A:E,1,0) -> Inferior | BA4: =VLOOKUP(AO4,'PGD03'!C:E,1,0) -> Bloco 2 vias fundo – Vapor | BB4: =VLOOKUP(AO4,'PGD04'!C:E,3,0) -> DN-40 | BC4: =VLOOKUP(AO4,'PGD04'!C:G,5,0) -> GEMÜ | BD4: =VLOOKUP(AN4,'PGD05'!A:E,1,0) -> Inferior | BE4: =VLOOKUP(AO4,'PGD05'!C:E,1,0) -> Bloco 2 vias fundo – Vapor | BF4: =VLOOKUP(AO4,'PGD05'!C:E,3,0) -> DN-40 | BG4: =VLOOKUP(AO4,'PGD05'!C:G,5,0) -> GEMÜ | BH4: =VLOOKUP(AN4,'PGD06'!A:E,1,0) -> Inferior | BI4: =VLOOKUP(AO4,'PGD06'!C:E,1,0) -> Bloco 2 vias fundo – Vapor | BJ4: =VLOOKUP(AO4,'PGD06'!C:E,3,0) -> DN-40 | BK4: =VLOOKUP(AO4,'PGD06'!C:G,5,0) -> GEMÜ | BL4: =VLOOKUP(AN4,'PGD07'!A:E,1,0) -> Inferior | BM4: =VLOOKUP(AO4,'PGD07'!C:E,1,0) -> Bloco 2 vias fundo – Vapor | BN4: =VLOOKUP(AO4,'PGD07'!C:E,3,0) -> DN-40 | BO4: =VLOOKUP(AO4,'PGD07'!C:G,5,0) -> GEMÜ | BP4: =VLOOKUP(AN4,'PGD08'!A:E,1,0) -> Inferior | BQ4: =VLOOKUP(AO4,'PGD08'!C:E,1,0) -> Bloco 2 vias fundo – Vapor | BR4: =VLOOKUP(AO4,'PGD08'!C:E,3,0) -> DN-40 | BS4: =VLOOKUP(AO4,'PGD08'!C:G,5,0) -> GEMÜ | BT4: =VLOOKUP(AN4,'PGD09'!A:E,1,0) -> Inferior | BU4: =VLOOKUP(AO4,'PGD09'!C:E,1,0) -> Bloco 2 vias fundo – Vapor | BV4: =VLOOKUP(AO4,'PGD09'!C:E,3,0) -> DN-40 | BW4: =VLOOKUP(AO4,'PGD09'!C:G,5,0) -> GEMÜ | BX4: =VLOOKUP(AN4,'PGD10'!A:E,1,0) -> Inferior | BY4: =VLOOKUP(AO4,'PGD10'!C:E,1,0) -> Bloco 2 vias fundo – Vapor | BZ4: =VLOOKUP(AO4,'PGD10'!C:E,3,0) -> DN-40 | CA4: =VLOOKUP(AO4,'PGD10'!C:G,5,0) -> GEMÜ | CB4: =VLOOKUP(AN4,'PGD11'!A:E,1,0) -> Inferior | CC4: =VLOOKUP(AO4,'PGD11'!C:E,1,0) -> Bloco 2 vias fundo – Vapor | CD4: =VLOOKUP(AO4,'PGD11'!C:E,3,0) -> DN-40 | CE4: =VLOOKUP(AO4,'PGD11'!C:G,5,0) -> GEMÜ | CF4: =VLOOKUP(AN4,'PGD12'!A:E,1,0) -> Inferior | CG4: =VLOOKUP(AO4,'PGD12'!C:E,1,0) -> Bloco 2 vias fundo – Vapor | CH4: =VLOOKUP(AO4,'PGD12'!C:E,3,0) -> DN-40 | CI4: =VLOOKUP(AO4,'PGD12'!C:G,5,0) -> ZDL | CJ4: =COUNTIF(AS4:CH4,CH4) -> 11 | CL4: Bloco válv. 3 vias coletor de amostra Entrada tanque | CM4: DN-15 | CN4: ZDL | CO4: =VLOOKUP(CL4,'BLD03'!C:E,1,0) -> Bloco válv. 3 vias coletor de amostra Entrada tanque | CP4: =VLOOKUP(CL4,'BLD03'!C:E,3,0) -> DN-15 | CQ4: =VLOOKUP(CL4,'BLD02'!C:G,5,0) -> ZDL | CR4: =COUNTIF(CL4:CP4,CP4) -> 2
B5: Bloco 2 vias fundo – fundo | C5: DN-40 | D5: GEMÜ | E5: =VLOOKUP(B5,'FTD02'!C:E,1,0) -> Bloco 2 vias fundo – fundo | F5: =VLOOKUP(B5,'FTD02'!C:E,3,0) -> DN-40 | G5: =VLOOKUP(B5,'FTD02'!C:G,5,0) -> GEMÜ | H5: =VLOOKUP(B5,'FTD03'!C:E,1,0) -> Bloco 2 vias fundo – fundo | I5: =VLOOKUP(B5,'FTD03'!C:E,3,0) -> DN-40 | J5: =VLOOKUP(B5,'FTD03'!C:G,5,0) -> GEMÜ | K5: =VLOOKUP(B5,'FTD04'!C:E,1,0) -> Bloco 2 vias fundo – fundo | L5: =VLOOKUP(B5,'FTD04'!C:E,3,0) -> DN-40 | M5: =VLOOKUP(B5,'FTD04'!C:G,5,0) -> GEMÜ | N5: =VLOOKUP(B5,'FTD05'!C:E,1,0) -> Bloco 2 vias fundo – fundo | O5: =VLOOKUP(B5,'FTD05'!C:E,3,0) -> DN-40 | P5: =VLOOKUP(B5,'FTD05'!C:G,5,0) -> GEMÜ | Q5: =VLOOKUP(B5,'FTD06'!C:E,1,0) -> Bloco 2 vias fundo – fundo | R5: =VLOOKUP(B5,'FTD06'!C:E,3,0) -> DN-40 | S5: =VLOOKUP(B5,'FTD06'!C:G,5,0) -> GEMÜ | T5: =VLOOKUP(B5,'FTD07'!C:E,1,0) -> Bloco 2 vias fundo – fundo | U5: =VLOOKUP(B5,'FTD07'!C:E,3,0) -> DN-40 | V5: =VLOOKUP(B5,'FTD07'!C:G,5,0) -> GEMÜ | W5: =VLOOKUP(B5,'FTD08'!C:E,1,0) -> Bloco 2 vias fundo – fundo | X5: =VLOOKUP(B5,'FTD08'!C:E,3,0) -> DN-40 | Y5: =VLOOKUP(B5,'FTD08'!C:G,5,0) -> GEMÜ | Z5: =VLOOKUP(B5,'FTD09'!C:E,1,0) -> Bloco 2 vias fundo – fundo | AA5: =VLOOKUP(B5,'FTD09'!C:E,3,0) -> DN-40 | AB5: =VLOOKUP(B5,'FTD09'!C:G,5,0) -> GEMÜ | AC5: =VLOOKUP(B5,'FTD10'!C:E,1,0) -> Bloco 2 vias fundo – fundo | AD5: =VLOOKUP(B5,'FTD10'!C:E,3,0) -> DN-40 | AE5: =VLOOKUP(B5,'FTD10'!C:G,5,0) -> GEMÜ | AF5: =VLOOKUP(B5,'FTD11'!C:E,1,0) -> Bloco 2 vias fundo – fundo | AG5: =VLOOKUP(B5,'FTD11'!C:E,3,0) -> DN-40 | AH5: =VLOOKUP(B5,'FTD11'!C:G,5,0) -> GEMÜ | AI5: =VLOOKUP(B5,'FTD12'!C:E,1,0) -> Bloco 2 vias fundo – fundo | AJ5: =VLOOKUP(B5,'FTD12'!C:E,3,0) -> DN-40 | AK5: =VLOOKUP(B5,'FTD12'!C:G,5,0) -> GEMÜ | AL5: =COUNTIF(E5:AJ5,AJ5) -> 11 | AN5: Inferior | AO5: Bloco válv. 3 vias coletor de amostra Dreno vapor | AP5: DN-15 | AQ5: Válvula manual | AR5: =VLOOKUP(AN5,'PGD02'!A:E,1,0) -> Inferior | AS5: =VLOOKUP(AO5,'PGD02'!C:E,1,0) -> Bloco válv. 3 vias coletor de amostra Dreno vapor | AT5: =VLOOKUP(AO5,'PGD02'!C:E,3,0) -> DN-15 | AU5: =VLOOKUP(AO5,'PGD02'!C:G,5,0) -> ZDL | AV5: =VLOOKUP(AN5,'PGD03'!A:E,1,0) -> Inferior | AW5: =VLOOKUP(AO5,'PGD03'!C:E,1,0) -> Bloco válv. 3 vias coletor de amostra Dreno vapor | AX5: =VLOOKUP(AO5,'PGD03'!C:E,3,0) -> DN-15 | AY5: =VLOOKUP(AO5,'PGD03'!C:G,5,0) -> ZDL | AZ5: =VLOOKUP(AN5,'PGD04'!A:E,1,0) -> Inferior | BA5: =VLOOKUP(AO5,'PGD03'!C:E,1,0) -> Bloco válv. 3 vias coletor de amostra Dreno vapor | BB5: =VLOOKUP(AO5,'PGD04'!C:E,3,0) -> DN-15 | BC5: =VLOOKUP(AO5,'PGD04'!C:G,5,0) -> ZDL | BD5: =VLOOKUP(AN5,'PGD05'!A:E,1,0) -> Inferior | BE5: =VLOOKUP(AO5,'PGD05'!C:E,1,0) -> Bloco válv. 3 vias coletor de amostra Dreno vapor | BF5: =VLOOKUP(AO5,'PGD05'!C:E,3,0) -> DN-15 | BG5: =VLOOKUP(AO5,'PGD05'!C:G,5,0) -> ZDL | BH5: =VLOOKUP(AN5,'PGD06'!A:E,1,0) -> Inferior | BI5: =VLOOKUP(AO5,'PGD06'!C:E,1,0) -> Bloco válv. 3 vias coletor de amostra Dreno vapor | BJ5: =VLOOKUP(AO5,'PGD06'!C:E,3,0) -> DN-15 | BK5: =VLOOKUP(AO5,'PGD06'!C:G,5,0) -> ZDL | BL5: =VLOOKUP(AN5,'PGD07'!A:E,1,0) -> Inferior | BM5: =VLOOKUP(AO5,'PGD07'!C:E,1,0) -> Bloco válv. 3 vias coletor de amostra Dreno vapor | BN5: =VLOOKUP(AO5,'PGD07'!C:E,3,0) -> DN-15 | BO5: =VLOOKUP(AO5,'PGD07'!C:G,5,0) -> ZDL | BP5: =VLOOKUP(AN5,'PGD08'!A:E,1,0) -> Inferior | BQ5: =VLOOKUP(AO5,'PGD08'!C:E,1,0) -> Bloco válv. 3 vias coletor de amostra Dreno vapor | BR5: =VLOOKUP(AO5,'PGD08'!C:E,3,0) -> DN-15 | BS5: =VLOOKUP(AO5,'PGD08'!C:G,5,0) -> ZDL | BT5: =VLOOKUP(AN5,'PGD09'!A:E,1,0) -> Inferior | BU5: =VLOOKUP(AO5,'PGD09'!C:E,1,0) -> Bloco válv. 3 vias coletor de amostra Dreno vapor | BV5: =VLOOKUP(AO5,'PGD09'!C:E,3,0) -> DN-15 | BW5: =VLOOKUP(AO5,'PGD09'!C:G,5,0) -> ZDL | BX5: =VLOOKUP(AN5,'PGD10'!A:E,1,0) -> Inferior | BY5: =VLOOKUP(AO5,'PGD10'!C:E,1,0) -> Bloco válv. 3 vias coletor de amostra Dreno vapor | BZ5: =VLOOKUP(AO5,'PGD10'!C:E,3,0) -> DN-15 | CA5: =VLOOKUP(AO5,'PGD10'!C:G,5,0) -> ZDL | CB5: =VLOOKUP(AN5,'PGD11'!A:E,1,0) -> Inferior | CC5: =VLOOKUP(AO5,'PGD11'!C:E,1,0) -> Bloco válv. 3 vias coletor de amostra Dreno vapor | CD5: =VLOOKUP(AO5,'PGD11'!C:E,3,0) -> DN-15 | CE5: =VLOOKUP(AO5,'PGD11'!C:G,5,0) -> ZDL | CF5: =VLOOKUP(AN5,'PGD12'!A:E,1,0) -> Inferior | CG5: =VLOOKUP(AO5,'PGD12'!C:E,1,0) -> Bloco válv. 3 vias coletor de amostra Dreno vapor | CH5: =VLOOKUP(AO5,'PGD12'!C:E,3,0) -> DN-15 | CI5: =VLOOKUP(AO5,'PGD12'!C:G,5,0) -> ZDL | CJ5: =COUNTIF(AS5:CH5,CH5) -> 11 | CL5: Bloco válv. 3 vias coletor de amostra Entrada vapor | CM5: DN-15 | CN5: ZDL | CO5: =VLOOKUP(CL5,'BLD03'!C:E,1,0) -> Bloco válv. 3 vias coletor de amostra Entrada vapor | CP5: =VLOOKUP(CL5,'BLD03'!C:E,3,0) -> DN-15 | CQ5: =VLOOKUP(CL5,'BLD02'!C:G,5,0) -> ZDL | CR5: =COUNTIF(CL5:CP5,CP5) -> 2
B6: Bloco 2 vias fundo – vapor | C6: DN-8 | D6: ZDL | E6: =VLOOKUP(B6,'FTD02'!C:E,1,0) -> Bloco 2 vias fundo – vapor | F6: =VLOOKUP(B6,'FTD02'!C:E,3,0) -> DN-8 | G6: =VLOOKUP(B6,'FTD02'!C:G,5,0) -> ZDL | H6: =VLOOKUP(B6,'FTD03'!C:E,1,0) -> Bloco 2 vias fundo – vapor | I6: =VLOOKUP(B6,'FTD03'!C:E,3,0) -> DN-8 | J6: =VLOOKUP(B6,'FTD03'!C:G,5,0) -> ZDL | K6: =VLOOKUP(B6,'FTD04'!C:E,1,0) -> Bloco 2 vias fundo – vapor | L6: =VLOOKUP(B6,'FTD04'!C:E,3,0) -> DN-8 | M6: =VLOOKUP(B6,'FTD04'!C:G,5,0) -> ZDL | N6: =VLOOKUP(B6,'FTD05'!C:E,1,0) -> Bloco 2 vias fundo – vapor | O6: =VLOOKUP(B6,'FTD05'!C:E,3,0) -> DN-8 | P6: =VLOOKUP(B6,'FTD05'!C:G,5,0) -> ZDL | Q6: =VLOOKUP(B6,'FTD06'!C:E,1,0) -> Bloco 2 vias fundo – vapor | R6: =VLOOKUP(B6,'FTD06'!C:E,3,0) -> DN-8 | S6: =VLOOKUP(B6,'FTD06'!C:G,5,0) -> GEMÜ | T6: =VLOOKUP(B6,'FTD07'!C:E,1,0) -> Bloco 2 vias fundo – vapor | U6: =VLOOKUP(B6,'FTD07'!C:E,3,0) -> DN-8 | V6: =VLOOKUP(B6,'FTD07'!C:G,5,0) -> ZDL | W6: =VLOOKUP(B6,'FTD08'!C:E,1,0) -> Bloco 2 vias fundo – vapor | X6: =VLOOKUP(B6,'FTD08'!C:E,3,0) -> DN-8 | Y6: =VLOOKUP(B6,'FTD08'!C:G,5,0) -> ZDL | Z6: =VLOOKUP(B6,'FTD09'!C:E,1,0) -> Bloco 2 vias fundo – vapor | AA6: =VLOOKUP(B6,'FTD09'!C:E,3,0) -> DN-8 | AB6: =VLOOKUP(B6,'FTD09'!C:G,5,0) -> ZDL | AC6: =VLOOKUP(B6,'FTD10'!C:E,1,0) -> Bloco 2 vias fundo – vapor | AD6: =VLOOKUP(B6,'FTD10'!C:E,3,0) -> DN-8 | AE6: =VLOOKUP(B6,'FTD10'!C:G,5,0) -> ZDL | AF6: =VLOOKUP(B6,'FTD11'!C:E,1,0) -> Bloco 2 vias fundo – vapor | AG6: =VLOOKUP(B6,'FTD11'!C:E,3,0) -> DN-8 | AH6: =VLOOKUP(B6,'FTD11'!C:G,5,0) -> ZDL | AI6: =VLOOKUP(B6,'FTD12'!C:E,1,0) -> Bloco 2 vias fundo – vapor | AJ6: =VLOOKUP(B6,'FTD12'!C:E,3,0) -> DN-8 | AK6: =VLOOKUP(B6,'FTD12'!C:G,5,0) -> ZDL | AL6: =COUNTIF(E6:AJ6,AJ6) -> 11 | AN6: Inferior | AO6: Bloco válv. 3 vias coletor de amostra Entrada tanque | AP6: DN-15 | AQ6: Válvula manual | AR6: =VLOOKUP(AN6,'PGD02'!A:E,1,0) -> Inferior | AS6: =VLOOKUP(AO6,'PGD02'!C:E,1,0) -> Bloco válv. 3 vias coletor de amostra Entrada tanque | AT6: =VLOOKUP(AO6,'PGD02'!C:E,3,0) -> DN-15 | AU6: =VLOOKUP(AO6,'PGD02'!C:G,5,0) -> ZDL | AV6: =VLOOKUP(AN6,'PGD03'!A:E,1,0) -> Inferior | AW6: =VLOOKUP(AO6,'PGD03'!C:E,1,0) -> Bloco válv. 3 vias coletor de amostra Entrada tanque | AX6: =VLOOKUP(AO6,'PGD03'!C:E,3,0) -> DN-15 | AY6: =VLOOKUP(AO6,'PGD03'!C:G,5,0) -> ZDL | AZ6: =VLOOKUP(AN6,'PGD04'!A:E,1,0) -> Inferior | BA6: =VLOOKUP(AO6,'PGD03'!C:E,1,0) -> Bloco válv. 3 vias coletor de amostra Entrada tanque | BB6: =VLOOKUP(AO6,'PGD04'!C:E,3,0) -> DN-15 | BC6: =VLOOKUP(AO6,'PGD04'!C:G,5,0) -> ZDL | BD6: =VLOOKUP(AN6,'PGD05'!A:E,1,0) -> Inferior | BE6: =VLOOKUP(AO6,'PGD05'!C:E,1,0) -> Bloco válv. 3 vias coletor de amostra Entrada tanque | BF6: =VLOOKUP(AO6,'PGD05'!C:E,3,0) -> DN-15 | BG6: =VLOOKUP(AO6,'PGD05'!C:G,5,0) -> ZDL | BH6: =VLOOKUP(AN6,'PGD06'!A:E,1,0) -> Inferior | BI6: =VLOOKUP(AO6,'PGD06'!C:E,1,0) -> Bloco válv. 3 vias coletor de amostra Entrada tanque | BJ6: =VLOOKUP(AO6,'PGD06'!C:E,3,0) -> DN-15 | BK6: =VLOOKUP(AO6,'PGD06'!C:G,5,0) -> ZDL | BL6: =VLOOKUP(AN6,'PGD07'!A:E,1,0) -> Inferior | BM6: =VLOOKUP(AO6,'PGD07'!C:E,1,0) -> Bloco válv. 3 vias coletor de amostra Entrada tanque | BN6: =VLOOKUP(AO6,'PGD07'!C:E,3,0) -> DN-15 | BO6: =VLOOKUP(AO6,'PGD07'!C:G,5,0) -> ZDL | BP6: =VLOOKUP(AN6,'PGD08'!A:E,1,0) -> Inferior | BQ6: =VLOOKUP(AO6,'PGD08'!C:E,1,0) -> Bloco válv. 3 vias coletor de amostra Entrada tanque | BR6: =VLOOKUP(AO6,'PGD08'!C:E,3,0) -> DN-15 | BS6: =VLOOKUP(AO6,'PGD08'!C:G,5,0) -> ZDL | BT6: =VLOOKUP(AN6,'PGD09'!A:E,1,0) -> Inferior | BU6: =VLOOKUP(AO6,'PGD09'!C:E,1,0) -> Bloco válv. 3 vias coletor de amostra Entrada tanque | BV6: =VLOOKUP(AO6,'PGD09'!C:E,3,0) -> DN-15 | BW6: =VLOOKUP(AO6,'PGD09'!C:G,5,0) -> ZDL | BX6: =VLOOKUP(AN6,'PGD10'!A:E,1,0) -> Inferior | BY6: =VLOOKUP(AO6,'PGD10'!C:E,1,0) -> Bloco válv. 3 vias coletor de amostra Entrada tanque | BZ6: =VLOOKUP(AO6,'PGD10'!C:E,3,0) -> DN-15 | CA6: =VLOOKUP(AO6,'PGD10'!C:G,5,0) -> ZDL | CB6: =VLOOKUP(AN6,'PGD11'!A:E,1,0) -> Inferior | CC6: =VLOOKUP(AO6,'PGD11'!C:E,1,0) -> Bloco válv. 3 vias coletor de amostra Entrada tanque | CD6: =VLOOKUP(AO6,'PGD11'!C:E,3,0) -> DN-15 | CE6: =VLOOKUP(AO6,'PGD11'!C:G,5,0) -> ZDL | CF6: =VLOOKUP(AN6,'PGD12'!A:E,1,0) -> Inferior | CG6: =VLOOKUP(AO6,'PGD12'!C:E,1,0) -> Bloco válv. 3 vias coletor de amostra Entrada tanque | CH6: =VLOOKUP(AO6,'PGD12'!C:E,3,0) -> DN-15 | CI6: =VLOOKUP(AO6,'PGD12'!C:G,5,0) -> ZDL | CJ6: =COUNTIF(AS6:CH6,CH6) -> 11 | CL6: Bloco válv. 3 vias coletor de amostra Dreno vapor | CM6: DN-15 | CN6: ZDL | CO6: =VLOOKUP(CL6,'BLD03'!C:E,1,0) -> Bloco válv. 3 vias coletor de amostra Dreno vapor | CP6: =VLOOKUP(CL6,'BLD03'!C:E,3,0) -> DN-15 | CQ6: =VLOOKUP(CL6,'BLD02'!C:G,5,0) -> ZDL | CR6: =COUNTIF(CL6:CP6,CP6) -> 2
B7: Bloco válv. 3 vias coletor de amostra Dreno vapor | C7: DN-15 | D7: ZDL | E7: =VLOOKUP(B7,'FTD02'!C:E,1,0) -> Bloco válv. 3 vias coletor de amostra Dreno vapor | F7: =VLOOKUP(B7,'FTD02'!C:E,3,0) -> DN-15 | G7: =VLOOKUP(B7,'FTD02'!C:G,5,0) -> ZDL | H7: =VLOOKUP(B7,'FTD03'!C:E,1,0) -> Bloco válv. 3 vias coletor de amostra Dreno vapor | I7: =VLOOKUP(B7,'FTD03'!C:E,3,0) -> DN-15 | J7: =VLOOKUP(B7,'FTD03'!C:G,5,0) -> ZDL | K7: =VLOOKUP(B7,'FTD04'!C:E,1,0) -> Bloco válv. 3 vias coletor de amostra Dreno vapor | L7: =VLOOKUP(B7,'FTD04'!C:E,3,0) -> DN-15 | M7: =VLOOKUP(B7,'FTD04'!C:G,5,0) -> ZDL | N7: =VLOOKUP(B7,'FTD05'!C:E,1,0) -> Bloco válv. 3 vias coletor de amostra Dreno vapor | O7: =VLOOKUP(B7,'FTD05'!C:E,3,0) -> DN-15 | P7: =VLOOKUP(B7,'FTD05'!C:G,5,0) -> ZDL | Q7: =VLOOKUP(B7,'FTD06'!C:E,1,0) -> Bloco válv. 3 vias coletor de amostra Dreno vapor | R7: =VLOOKUP(B7,'FTD06'!C:E,3,0) -> DN-15 | S7: =VLOOKUP(B7,'FTD06'!C:G,5,0) -> ZDL | T7: =VLOOKUP(B7,'FTD07'!C:E,1,0) -> Bloco válv. 3 vias coletor de amostra Dreno vapor | U7: =VLOOKUP(B7,'FTD07'!C:E,3,0) -> DN-15 | V7: =VLOOKUP(B7,'FTD07'!C:G,5,0) -> ZDL | W7: =VLOOKUP(B7,'FTD08'!C:E,1,0) -> Bloco válv. 3 vias coletor de amostra Dreno vapor | X7: =VLOOKUP(B7,'FTD08'!C:E,3,0) -> DN-15 | Y7: =VLOOKUP(B7,'FTD08'!C:G,5,0) -> ZDL | Z7: =VLOOKUP(B7,'FTD09'!C:E,1,0) -> Bloco válv. 3 vias coletor de amostra Dreno vapor | AA7: =VLOOKUP(B7,'FTD09'!C:E,3,0) -> DN-15 | AB7: =VLOOKUP(B7,'FTD09'!C:G,5,0) -> ZDL | AC7: =VLOOKUP(B7,'FTD10'!C:E,1,0) -> Bloco válv. 3 vias coletor de amostra Dreno vapor | AD7: =VLOOKUP(B7,'FTD10'!C:E,3,0) -> DN-15 | AE7: =VLOOKUP(B7,'FTD10'!C:G,5,0) -> ZDL | AF7: =VLOOKUP(B7,'FTD11'!C:E,1,0) -> Bloco válv. 3 vias coletor de amostra Dreno vapor | AG7: =VLOOKUP(B7,'FTD11'!C:E,3,0) -> DN-15 | AH7: =VLOOKUP(B7,'FTD11'!C:G,5,0) -> ZDL | AI7: =VLOOKUP(B7,'FTD12'!C:E,1,0) -> Bloco válv. 3 vias coletor de amostra Dreno vapor | AJ7: =VLOOKUP(B7,'FTD12'!C:E,3,0) -> DN-15 | AK7: =VLOOKUP(B7,'FTD12'!C:G,5,0) -> ZDL | AL7: =COUNTIF(E7:AJ7,AJ7) -> 11 | AN7: Inferior | AO7: Bloco válv. 3 vias coletor de amostra Entrada vapor | AP7: DN-15 | AQ7: Válvula manual | AR7: =VLOOKUP(AN7,'PGD02'!A:E,1,0) -> Inferior | AS7: =VLOOKUP(AO7,'PGD02'!C:E,1,0) -> Bloco válv. 3 vias coletor de amostra Entrada vapor | AT7: =VLOOKUP(AO7,'PGD02'!C:E,3,0) -> DN-15 | AU7: =VLOOKUP(AO7,'PGD02'!C:G,5,0) -> ZDL | AV7: =VLOOKUP(AN7,'PGD03'!A:E,1,0) -> Inferior | AW7: =VLOOKUP(AO7,'PGD03'!C:E,1,0) -> Bloco válv. 3 vias coletor de amostra Entrada vapor | AX7: =VLOOKUP(AO7,'PGD03'!C:E,3,0) -> DN-15 | AY7: =VLOOKUP(AO7,'PGD03'!C:G,5,0) -> ZDL | AZ7: =VLOOKUP(AN7,'PGD04'!A:E,1,0) -> Inferior | BA7: =VLOOKUP(AO7,'PGD03'!C:E,1,0) -> Bloco válv. 3 vias coletor de amostra Entrada vapor | BB7: =VLOOKUP(AO7,'PGD04'!C:E,3,0) -> DN-15 | BC7: =VLOOKUP(AO7,'PGD04'!C:G,5,0) -> ZDL | BD7: =VLOOKUP(AN7,'PGD05'!A:E,1,0) -> Inferior | BE7: =VLOOKUP(AO7,'PGD05'!C:E,1,0) -> Bloco válv. 3 vias coletor de amostra Entrada vapor | BF7: =VLOOKUP(AO7,'PGD05'!C:E,3,0) -> DN-15 | BG7: =VLOOKUP(AO7,'PGD05'!C:G,5,0) -> ZDL | BH7: =VLOOKUP(AN7,'PGD06'!A:E,1,0) -> Inferior | BI7: =VLOOKUP(AO7,'PGD06'!C:E,1,0) -> Bloco válv. 3 vias coletor de amostra Entrada vapor | BJ7: =VLOOKUP(AO7,'PGD06'!C:E,3,0) -> DN-15 | BK7: =VLOOKUP(AO7,'PGD06'!C:G,5,0) -> ZDL | BL7: =VLOOKUP(AN7,'PGD07'!A:E,1,0) -> Inferior | BM7: =VLOOKUP(AO7,'PGD07'!C:E,1,0) -> Bloco válv. 3 vias coletor de amostra Entrada vapor | BN7: =VLOOKUP(AO7,'PGD07'!C:E,3,0) -> DN-15 | BO7: =VLOOKUP(AO7,'PGD07'!C:G,5,0) -> ZDL | BP7: =VLOOKUP(AN7,'PGD08'!A:E,1,0) -> Inferior | BQ7: =VLOOKUP(AO7,'PGD08'!C:E,1,0) -> Bloco válv. 3 vias coletor de amostra Entrada vapor | BR7: =VLOOKUP(AO7,'PGD08'!C:E,3,0) -> DN-15 | BS7: =VLOOKUP(AO7,'PGD08'!C:G,5,0) -> ZDL | BT7: =VLOOKUP(AN7,'PGD09'!A:E,1,0) -> Inferior | BU7: =VLOOKUP(AO7,'PGD09'!C:E,1,0) -> Bloco válv. 3 vias coletor de amostra Entrada vapor | BV7: =VLOOKUP(AO7,'PGD09'!C:E,3,0) -> DN-15 | BW7: =VLOOKUP(AO7,'PGD09'!C:G,5,0) -> ZDL | BX7: =VLOOKUP(AN7,'PGD10'!A:E,1,0) -> Inferior | BY7: =VLOOKUP(AO7,'PGD10'!C:E,1,0) -> Bloco válv. 3 vias coletor de amostra Entrada vapor | BZ7: =VLOOKUP(AO7,'PGD10'!C:E,3,0) -> DN-15 | CA7: =VLOOKUP(AO7,'PGD10'!C:G,5,0) -> ZDL | CB7: =VLOOKUP(AN7,'PGD11'!A:E,1,0) -> Inferior | CC7: =VLOOKUP(AO7,'PGD11'!C:E,1,0) -> Bloco válv. 3 vias coletor de amostra Entrada vapor | CD7: =VLOOKUP(AO7,'PGD11'!C:E,3,0) -> DN-15 | CE7: =VLOOKUP(AO7,'PGD11'!C:G,5,0) -> ZDL | CF7: =VLOOKUP(AN7,'PGD12'!A:E,1,0) -> Inferior | CG7: =VLOOKUP(AO7,'PGD12'!C:E,1,0) -> Bloco válv. 3 vias coletor de amostra Entrada vapor | CH7: =VLOOKUP(AO7,'PGD12'!C:E,3,0) -> DN-15 | CI7: =VLOOKUP(AO7,'PGD12'!C:G,5,0) -> ZDL | CJ7: =COUNTIF(AS7:CH7,CH7) -> 11 | CL7: Bloco 2 vias fundo - fundo | CM7: DN-40 | CN7: GEMÜ | CO7: =VLOOKUP(CL7,'BLD03'!C:E,1,0) -> Bloco 2 vias fundo - fundo | CP7: =VLOOKUP(CL7,'BLD03'!C:E,3,0) -> DN-40 | CQ7: =VLOOKUP(CL7,'BLD02'!C:G,5,0) -> GEMÜ | CR7: =COUNTIF(CL7:CP7,CP7) -> 2
B8: Bloco válv. 3 vias coletor de amostra Entrada tanque | C8: DN-15 | D8: ZDL | E8: =VLOOKUP(B8,'FTD02'!C:E,1,0) -> Bloco válv. 3 vias coletor de amostra Entrada tanque | F8: =VLOOKUP(B8,'FTD02'!C:E,3,0) -> DN-15 | G8: =VLOOKUP(B8,'FTD02'!C:G,5,0) -> ZDL | H8: =VLOOKUP(B8,'FTD03'!C:E,1,0) -> Bloco válv. 3 vias coletor de amostra Entrada tanque | I8: =VLOOKUP(B8,'FTD03'!C:E,3,0) -> DN-15 | J8: =VLOOKUP(B8,'FTD03'!C:G,5,0) -> ZDL | K8: =VLOOKUP(B8,'FTD04'!C:E,1,0) -> Bloco válv. 3 vias coletor de amostra Entrada tanque | L8: =VLOOKUP(B8,'FTD04'!C:E,3,0) -> DN-15 | M8: =VLOOKUP(B8,'FTD04'!C:G,5,0) -> ZDL | N8: =VLOOKUP(B8,'FTD05'!C:E,1,0) -> Bloco válv. 3 vias coletor de amostra Entrada tanque | O8: =VLOOKUP(B8,'FTD05'!C:E,3,0) -> DN-15 | P8: =VLOOKUP(B8,'FTD05'!C:G,5,0) -> ZDL | Q8: =VLOOKUP(B8,'FTD06'!C:E,1,0) -> Bloco válv. 3 vias coletor de amostra Entrada tanque | R8: =VLOOKUP(B8,'FTD06'!C:E,3,0) -> DN-15 | S8: =VLOOKUP(B8,'FTD06'!C:G,5,0) -> ZDL | T8: =VLOOKUP(B8,'FTD07'!C:E,1,0) -> Bloco válv. 3 vias coletor de amostra Entrada tanque | U8: =VLOOKUP(B8,'FTD07'!C:E,3,0) -> DN-15 | V8: =VLOOKUP(B8,'FTD07'!C:G,5,0) -> ZDL | W8: =VLOOKUP(B8,'FTD08'!C:E,1,0) -> Bloco válv. 3 vias coletor de amostra Entrada tanque | X8: =VLOOKUP(B8,'FTD08'!C:E,3,0) -> DN-15 | Y8: =VLOOKUP(B8,'FTD08'!C:G,5,0) -> ZDL | Z8: =VLOOKUP(B8,'FTD09'!C:E,1,0) -> Bloco válv. 3 vias coletor de amostra Entrada tanque | AA8: =VLOOKUP(B8,'FTD09'!C:E,3,0) -> DN-15 | AB8: =VLOOKUP(B8,'FTD09'!C:G,5,0) -> ZDL | AC8: =VLOOKUP(B8,'FTD10'!C:E,1,0) -> Bloco válv. 3 vias coletor de amostra Entrada tanque | AD8: =VLOOKUP(B8,'FTD10'!C:E,3,0) -> DN-15 | AE8: =VLOOKUP(B8,'FTD10'!C:G,5,0) -> ZDL | AF8: =VLOOKUP(B8,'FTD11'!C:E,1,0) -> Bloco válv. 3 vias coletor de amostra Entrada tanque | AG8: =VLOOKUP(B8,'FTD11'!C:E,3,0) -> DN-15 | AH8: =VLOOKUP(B8,'FTD11'!C:G,5,0) -> ZDL | AI8: =VLOOKUP(B8,'FTD12'!C:E,1,0) -> Bloco válv. 3 vias coletor de amostra Entrada tanque | AJ8: =VLOOKUP(B8,'FTD12'!C:E,3,0) -> DN-15 | AK8: =VLOOKUP(B8,'FTD12'!C:G,5,0) -> ZDL | AL8: =COUNTIF(E8:AJ8,AJ8) -> 11 | AN8: Inferior | AO8: CIP BV | AP8: DN-40 | AQ8: BV - 09.25-2 | AR8: =VLOOKUP(AN8,'PGD02'!A:E,1,0) -> Inferior | AS8: =VLOOKUP(AO8,'PGD02'!C:E,1,0) -> CIP BV | AT8: =VLOOKUP(AO8,'PGD02'!C:E,3,0) -> DN-40 | AU8: =VLOOKUP(AO8,'PGD02'!C:G,5,0) -> GEMÜ | AV8: =VLOOKUP(AN8,'PGD03'!A:E,1,0) -> Inferior | AW8: =VLOOKUP(AO8,'PGD03'!C:E,1,0) -> CIP BV | AX8: =VLOOKUP(AO8,'PGD03'!C:E,3,0) -> DN-40 | AY8: =VLOOKUP(AO8,'PGD03'!C:G,5,0) -> GEMÜ | AZ8: =VLOOKUP(AN8,'PGD04'!A:E,1,0) -> Inferior | BA8: =VLOOKUP(AO8,'PGD03'!C:E,1,0) -> CIP BV | BB8: =VLOOKUP(AO8,'PGD04'!C:E,3,0) -> DN-40 | BC8: =VLOOKUP(AO8,'PGD04'!C:G,5,0) -> GEMÜ | BD8: =VLOOKUP(AN8,'PGD05'!A:E,1,0) -> Inferior | BE8: =VLOOKUP(AO8,'PGD05'!C:E,1,0) -> CIP BV | BF8: =VLOOKUP(AO8,'PGD05'!C:E,3,0) -> DN-40 | BG8: =VLOOKUP(AO8,'PGD05'!C:G,5,0) -> GEMÜ | BH8: =VLOOKUP(AN8,'PGD06'!A:E,1,0) -> Inferior | BI8: =VLOOKUP(AO8,'PGD06'!C:E,1,0) -> CIP BV | BJ8: =VLOOKUP(AO8,'PGD06'!C:E,3,0) -> DN-40 | BK8: =VLOOKUP(AO8,'PGD06'!C:G,5,0) -> GEMÜ | BL8: =VLOOKUP(AN8,'PGD07'!A:E,1,0) -> Inferior | BM8: =VLOOKUP(AO8,'PGD07'!C:E,1,0) -> CIP BV | BN8: =VLOOKUP(AO8,'PGD07'!C:E,3,0) -> DN-40 | BO8: =VLOOKUP(AO8,'PGD07'!C:G,5,0) -> GEMÜ | BP8: =VLOOKUP(AN8,'PGD08'!A:E,1,0) -> Inferior | BQ8: =VLOOKUP(AO8,'PGD08'!C:E,1,0) -> CIP BV | BR8: =VLOOKUP(AO8,'PGD08'!C:E,3,0) -> DN-40 | BS8: =VLOOKUP(AO8,'PGD08'!C:G,5,0) -> GEMÜ | BT8: =VLOOKUP(AN8,'PGD09'!A:E,1,0) -> Inferior | BU8: =VLOOKUP(AO8,'PGD09'!C:E,1,0) -> CIP BV | BV8: =VLOOKUP(AO8,'PGD09'!C:E,3,0) -> DN-40 | BW8: =VLOOKUP(AO8,'PGD09'!C:G,5,0) -> GEMÜ | BX8: =VLOOKUP(AN8,'PGD10'!A:E,1,0) -> Inferior | BY8: =VLOOKUP(AO8,'PGD10'!C:E,1,0) -> CIP BV | BZ8: =VLOOKUP(AO8,'PGD10'!C:E,3,0) -> DN-40 | CA8: =VLOOKUP(AO8,'PGD10'!C:G,5,0) -> GEMÜ | CB8: =VLOOKUP(AN8,'PGD11'!A:E,1,0) -> Inferior | CC8: =VLOOKUP(AO8,'PGD11'!C:E,1,0) -> CIP BV | CD8: =VLOOKUP(AO8,'PGD11'!C:E,3,0) -> DN-40 | CE8: =VLOOKUP(AO8,'PGD11'!C:G,5,0) -> GEMÜ | CF8: =VLOOKUP(AN8,'PGD12'!A:E,1,0) -> Inferior | CG8: =VLOOKUP(AO8,'PGD12'!C:E,1,0) -> CIP BV | CH8: =VLOOKUP(AO8,'PGD12'!C:E,3,0) -> DN-40 | CI8: =VLOOKUP(AO8,'PGD12'!C:G,5,0) -> GEMÜ | CJ8: =COUNTIF(AS8:CH8,CH8) -> 11 | CL8: Transferência BV | CM8: DN-40 | CN8: GEMÜ | CO8: =VLOOKUP(CL8,'BLD03'!C:E,1,0) -> Transferência BV | CP8: =VLOOKUP(CL8,'BLD03'!C:E,3,0) -> DN-40 | CQ8: =VLOOKUP(CL8,'BLD02'!C:G,5,0) -> GEMÜ | CR8: =COUNTIF(CL8:CP8,CP8) -> 2
B9: Bloco válv. 3 vias coletor de amostra Entrada vapor | C9: DN-15 | D9: ZDL | E9: =VLOOKUP(B9,'FTD02'!C:E,1,0) -> Bloco válv. 3 vias coletor de amostra Entrada vapor | F9: =VLOOKUP(B9,'FTD02'!C:E,3,0) -> DN-15 | G9: =VLOOKUP(B9,'FTD02'!C:G,5,0) -> ZDL | H9: =VLOOKUP(B9,'FTD03'!C:E,1,0) -> Bloco válv. 3 vias coletor de amostra Entrada vapor | I9: =VLOOKUP(B9,'FTD03'!C:E,3,0) -> DN-15 | J9: =VLOOKUP(B9,'FTD03'!C:G,5,0) -> ZDL | K9: =VLOOKUP(B9,'FTD04'!C:E,1,0) -> Bloco válv. 3 vias coletor de amostra Entrada vapor | L9: =VLOOKUP(B9,'FTD04'!C:E,3,0) -> DN-15 | M9: =VLOOKUP(B9,'FTD04'!C:G,5,0) -> ZDL | N9: =VLOOKUP(B9,'FTD05'!C:E,1,0) -> Bloco válv. 3 vias coletor de amostra Entrada vapor | O9: =VLOOKUP(B9,'FTD05'!C:E,3,0) -> DN-15 | P9: =VLOOKUP(B9,'FTD05'!C:G,5,0) -> ZDL | Q9: =VLOOKUP(B9,'FTD06'!C:E,1,0) -> Bloco válv. 3 vias coletor de amostra Entrada vapor | R9: =VLOOKUP(B9,'FTD06'!C:E,3,0) -> DN-15 | S9: =VLOOKUP(B9,'FTD06'!C:G,5,0) -> ZDL | T9: =VLOOKUP(B9,'FTD07'!C:E,1,0) -> Bloco válv. 3 vias coletor de amostra Entrada vapor | U9: =VLOOKUP(B9,'FTD07'!C:E,3,0) -> DN-15 | V9: =VLOOKUP(B9,'FTD07'!C:G,5,0) -> ZDL | W9: =VLOOKUP(B9,'FTD08'!C:E,1,0) -> Bloco válv. 3 vias coletor de amostra Entrada vapor | X9: =VLOOKUP(B9,'FTD08'!C:E,3,0) -> DN-15 | Y9: =VLOOKUP(B9,'FTD08'!C:G,5,0) -> ZDL | Z9: =VLOOKUP(B9,'FTD09'!C:E,1,0) -> Bloco válv. 3 vias coletor de amostra Entrada vapor | AA9: =VLOOKUP(B9,'FTD09'!C:E,3,0) -> DN-15 | AB9: =VLOOKUP(B9,'FTD09'!C:G,5,0) -> ZDL | AC9: =VLOOKUP(B9,'FTD10'!C:E,1,0) -> Bloco válv. 3 vias coletor de amostra Entrada vapor | AD9: =VLOOKUP(B9,'FTD10'!C:E,3,0) -> DN-15 | AE9: =VLOOKUP(B9,'FTD10'!C:G,5,0) -> ZDL | AF9: =VLOOKUP(B9,'FTD11'!C:E,1,0) -> Bloco válv. 3 vias coletor de amostra Entrada vapor | AG9: =VLOOKUP(B9,'FTD11'!C:E,3,0) -> DN-15 | AH9: =VLOOKUP(B9,'FTD11'!C:G,5,0) -> ZDL | AI9: =VLOOKUP(B9,'FTD12'!C:E,1,0) -> Bloco válv. 3 vias coletor de amostra Entrada vapor | AJ9: =VLOOKUP(B9,'FTD12'!C:E,3,0) -> DN-15 | AK9: =VLOOKUP(B9,'FTD12'!C:G,5,0) -> ZDL | AL9: =COUNTIF(E9:AJ9,AJ9) -> 11 | AN9: Inferior | AO9: Descarte BV | AP9: DN-40 | AQ9: BV - 09.25-3 | AR9: =VLOOKUP(AN9,'PGD02'!A:E,1,0) -> Inferior | AS9: =VLOOKUP(AO9,'PGD02'!C:E,1,0) -> Descarte BV | AT9: =VLOOKUP(AO9,'PGD02'!C:E,3,0) -> DN-40 | AU9: =VLOOKUP(AO9,'PGD02'!C:G,5,0) -> GEMÜ | AV9: =VLOOKUP(AN9,'PGD03'!A:E,1,0) -> Inferior | AW9: =VLOOKUP(AO9,'PGD03'!C:E,1,0) -> Descarte BV | AX9: =VLOOKUP(AO9,'PGD03'!C:E,3,0) -> DN-40 | AY9: =VLOOKUP(AO9,'PGD03'!C:G,5,0) -> GEMÜ | AZ9: =VLOOKUP(AN9,'PGD04'!A:E,1,0) -> Inferior | BA9: =VLOOKUP(AO9,'PGD03'!C:E,1,0) -> Descarte BV | BB9: =VLOOKUP(AO9,'PGD04'!C:E,3,0) -> DN-40 | BC9: =VLOOKUP(AO9,'PGD04'!C:G,5,0) -> GEMÜ | BD9: =VLOOKUP(AN9,'PGD05'!A:E,1,0) -> Inferior | BE9: =VLOOKUP(AO9,'PGD05'!C:E,1,0) -> Descarte BV | BF9: =VLOOKUP(AO9,'PGD05'!C:E,3,0) -> DN-40 | BG9: =VLOOKUP(AO9,'PGD05'!C:G,5,0) -> GEMÜ | BH9: =VLOOKUP(AN9,'PGD06'!A:E,1,0) -> Inferior | BI9: =VLOOKUP(AO9,'PGD06'!C:E,1,0) -> Descarte BV | BJ9: =VLOOKUP(AO9,'PGD06'!C:E,3,0) -> DN-40 | BK9: =VLOOKUP(AO9,'PGD06'!C:G,5,0) -> GEMÜ | BL9: =VLOOKUP(AN9,'PGD07'!A:E,1,0) -> Inferior | BM9: =VLOOKUP(AO9,'PGD07'!C:E,1,0) -> Descarte BV | BN9: =VLOOKUP(AO9,'PGD07'!C:E,3,0) -> DN-40 | BO9: =VLOOKUP(AO9,'PGD07'!C:G,5,0) -> GEMÜ | BP9: =VLOOKUP(AN9,'PGD08'!A:E,1,0) -> Inferior | BQ9: =VLOOKUP(AO9,'PGD08'!C:E,1,0) -> Descarte BV | BR9: =VLOOKUP(AO9,'PGD08'!C:E,3,0) -> DN-40 | BS9: =VLOOKUP(AO9,'PGD08'!C:G,5,0) -> GEMÜ | BT9: =VLOOKUP(AN9,'PGD09'!A:E,1,0) -> Inferior | BU9: =VLOOKUP(AO9,'PGD09'!C:E,1,0) -> Descarte BV | BV9: =VLOOKUP(AO9,'PGD09'!C:E,3,0) -> DN-40 | BW9: =VLOOKUP(AO9,'PGD09'!C:G,5,0) -> GEMÜ | BX9: =VLOOKUP(AN9,'PGD10'!A:E,1,0) -> Inferior | BY9: =VLOOKUP(AO9,'PGD10'!C:E,1,0) -> Descarte BV | BZ9: =VLOOKUP(AO9,'PGD10'!C:E,3,0) -> DN-40 | CA9: =VLOOKUP(AO9,'PGD10'!C:G,5,0) -> GEMÜ | CB9: =VLOOKUP(AN9,'PGD11'!A:E,1,0) -> Inferior | CC9: =VLOOKUP(AO9,'PGD11'!C:E,1,0) -> Descarte BV | CD9: =VLOOKUP(AO9,'PGD11'!C:E,3,0) -> DN-40 | CE9: =VLOOKUP(AO9,'PGD11'!C:G,5,0) -> GEMÜ | CF9: =VLOOKUP(AN9,'PGD12'!A:E,1,0) -> Inferior | CG9: =VLOOKUP(AO9,'PGD12'!C:E,1,0) -> Descarte BV | CH9: =VLOOKUP(AO9,'PGD12'!C:E,3,0) -> DN-40 | CI9: =VLOOKUP(AO9,'PGD12'!C:G,5,0) -> GEMÜ | CJ9: =COUNTIF(AS9:CH9,CH9) -> 11 | CL9: CIP BV | CM9: DN-40 | CN9: GEMÜ | CO9: =VLOOKUP(CL9,'BLD03'!C:E,1,0) -> CIP BV | CP9: =VLOOKUP(CL9,'BLD03'!C:E,3,0) -> DN-40 | CQ9: =VLOOKUP(CL9,'BLD02'!C:G,5,0) -> GEMÜ | CR9: =COUNTIF(CL9:CP9,CP9) -> 2
B10: CIP BV fundo | C10: DN-40 | D10: GEMÜ | E10: =VLOOKUP(B10,'FTD02'!C:E,1,0) -> CIP BV fundo | F10: =VLOOKUP(B10,'FTD02'!C:E,3,0) -> DN-40 | G10: =VLOOKUP(B10,'FTD02'!C:G,5,0) -> GEMÜ | H10: =VLOOKUP(B10,'FTD03'!C:E,1,0) -> CIP BV fundo | I10: =VLOOKUP(B10,'FTD03'!C:E,3,0) -> DN-40 | J10: =VLOOKUP(B10,'FTD03'!C:G,5,0) -> GEMÜ | K10: =VLOOKUP(B10,'FTD04'!C:E,1,0) -> CIP BV fundo | L10: =VLOOKUP(B10,'FTD04'!C:E,3,0) -> DN-40 | M10: =VLOOKUP(B10,'FTD04'!C:G,5,0) -> GEMÜ | N10: =VLOOKUP(B10,'FTD05'!C:E,1,0) -> CIP BV fundo | O10: =VLOOKUP(B10,'FTD05'!C:E,3,0) -> DN-40 | P10: =VLOOKUP(B10,'FTD05'!C:G,5,0) -> GEMÜ | Q10: =VLOOKUP(B10,'FTD06'!C:E,1,0) -> CIP BV fundo | R10: =VLOOKUP(B10,'FTD06'!C:E,3,0) -> DN-40 | S10: =VLOOKUP(B10,'FTD06'!C:G,5,0) -> GEMÜ | T10: =VLOOKUP(B10,'FTD07'!C:E,1,0) -> CIP BV fundo | U10: =VLOOKUP(B10,'FTD07'!C:E,3,0) -> DN-40 | V10: =VLOOKUP(B10,'FTD07'!C:G,5,0) -> GEMÜ | W10: =VLOOKUP(B10,'FTD08'!C:E,1,0) -> CIP BV fundo | X10: =VLOOKUP(B10,'FTD08'!C:E,3,0) -> DN-40 | Y10: =VLOOKUP(B10,'FTD08'!C:G,5,0) -> GEMÜ | Z10: =VLOOKUP(B10,'FTD09'!C:E,1,0) -> CIP BV fundo | AA10: =VLOOKUP(B10,'FTD09'!C:E,3,0) -> DN-40 | AB10: =VLOOKUP(B10,'FTD09'!C:G,5,0) -> GEMÜ | AC10: =VLOOKUP(B10,'FTD10'!C:E,1,0) -> CIP BV fundo | AD10: =VLOOKUP(B10,'FTD10'!C:E,3,0) -> DN-40 | AE10: =VLOOKUP(B10,'FTD10'!C:G,5,0) -> GEMÜ | AF10: =VLOOKUP(B10,'FTD11'!C:E,1,0) -> CIP BV fundo | AG10: =VLOOKUP(B10,'FTD11'!C:E,3,0) -> DN-40 | AH10: =VLOOKUP(B10,'FTD11'!C:G,5,0) -> GEMÜ | AI10: =VLOOKUP(B10,'FTD12'!C:E,1,0) -> CIP BV fundo | AJ10: =VLOOKUP(B10,'FTD12'!C:E,3,0) -> DN-40 | AK10: =VLOOKUP(B10,'FTD12'!C:G,5,0) -> GEMÜ | AL10: =COUNTIF(E10:AJ10,AJ10) -> 11 | AN10: Superior | AO10: Bloqueio entrada de ar pré filtro absoluto | AP10: DN-40 | AQ10: Válvula manual | AR10: =VLOOKUP(AN10,'PGD02'!A:E,1,0) -> Superior | AS10: =VLOOKUP(AO10,'PGD02'!C:E,1,0) -> Bloqueio entrada de ar pré filtro absoluto | AT10: =VLOOKUP(AO10,'PGD02'!C:E,3,0) -> DN-40 | AU10: =VLOOKUP(AO10,'PGD02'!C:G,5,0) -> GEMÜ | AV10: =VLOOKUP(AN10,'PGD03'!A:E,1,0) -> Superior | AW10: =VLOOKUP(AO10,'PGD03'!C:E,1,0) -> Bloqueio entrada de ar pré filtro absoluto | AX10: =VLOOKUP(AO10,'PGD03'!C:E,3,0) -> DN-40 | AY10: =VLOOKUP(AO10,'PGD03'!C:G,5,0) -> GEMÜ | AZ10: =VLOOKUP(AN10,'PGD04'!A:E,1,0) -> Superior | BA10: =VLOOKUP(AO10,'PGD03'!C:E,1,0) -> Bloqueio entrada de ar pré filtro absoluto | BB10: =VLOOKUP(AO10,'PGD04'!C:E,3,0) -> DN-40 | BC10: =VLOOKUP(AO10,'PGD04'!C:G,5,0) -> GEMÜ | BD10: =VLOOKUP(AN10,'PGD05'!A:E,1,0) -> Superior | BE10: =VLOOKUP(AO10,'PGD05'!C:E,1,0) -> Bloqueio entrada de ar pré filtro absoluto | BF10: =VLOOKUP(AO10,'PGD05'!C:E,3,0) -> DN-40 | BG10: =VLOOKUP(AO10,'PGD05'!C:G,5,0) -> GEMÜ | BH10: =VLOOKUP(AN10,'PGD06'!A:E,1,0) -> Superior | BI10: =VLOOKUP(AO10,'PGD06'!C:E,1,0) -> Bloqueio entrada de ar pré filtro absoluto | BJ10: =VLOOKUP(AO10,'PGD06'!C:E,3,0) -> DN-40 | BK10: =VLOOKUP(AO10,'PGD06'!C:G,5,0) -> GEMÜ | BL10: =VLOOKUP(AN10,'PGD07'!A:E,1,0) -> Superior | BM10: =VLOOKUP(AO10,'PGD07'!C:E,1,0) -> Bloqueio entrada de ar pré filtro absoluto | BN10: =VLOOKUP(AO10,'PGD07'!C:E,3,0) -> DN-40 | BO10: =VLOOKUP(AO10,'PGD07'!C:G,5,0) -> GEMÜ | BP10: =VLOOKUP(AN10,'PGD08'!A:E,1,0) -> Superior | BQ10: =VLOOKUP(AO10,'PGD08'!C:E,1,0) -> Bloqueio entrada de ar pré filtro absoluto | BR10: =VLOOKUP(AO10,'PGD08'!C:E,3,0) -> DN-40 | BS10: =VLOOKUP(AO10,'PGD08'!C:G,5,0) -> GEMÜ | BT10: =VLOOKUP(AN10,'PGD09'!A:E,1,0) -> Superior | BU10: =VLOOKUP(AO10,'PGD09'!C:E,1,0) -> Bloqueio entrada de ar pré filtro absoluto | BV10: =VLOOKUP(AO10,'PGD09'!C:E,3,0) -> DN-40 | BW10: =VLOOKUP(AO10,'PGD09'!C:G,5,0) -> GEMÜ | BX10: =VLOOKUP(AN10,'PGD10'!A:E,1,0) -> Superior | BY10: =VLOOKUP(AO10,'PGD10'!C:E,1,0) -> Bloqueio entrada de ar pré filtro absoluto | BZ10: =VLOOKUP(AO10,'PGD10'!C:E,3,0) -> DN-40 | CA10: =VLOOKUP(AO10,'PGD10'!C:G,5,0) -> GEMÜ | CB10: =VLOOKUP(AN10,'PGD11'!A:E,1,0) -> Superior | CC10: =VLOOKUP(AO10,'PGD11'!C:E,1,0) -> Bloqueio entrada de ar pré filtro absoluto | CD10: =VLOOKUP(AO10,'PGD11'!C:E,3,0) -> DN-40 | CE10: =VLOOKUP(AO10,'PGD11'!C:G,5,0) -> GEMÜ | CF10: =VLOOKUP(AN10,'PGD12'!A:E,1,0) -> Superior | CG10: =VLOOKUP(AO10,'PGD12'!C:E,1,0) -> Bloqueio entrada de ar pré filtro absoluto | CH10: =VLOOKUP(AO10,'PGD12'!C:E,3,0) -> DN-40 | CI10: =VLOOKUP(AO10,'PGD12'!C:G,5,0) -> GEMÜ | CJ10: =COUNTIF(AS10:CH10,CH10) -> 11 | CL10: Descarte BV | CM10: DN-40 | CN10: GEMÜ | CO10: =VLOOKUP(CL10,'BLD03'!C:E,1,0) -> Descarte BV | CP10: =VLOOKUP(CL10,'BLD03'!C:E,3,0) -> DN-40 | CQ10: =VLOOKUP(CL10,'BLD02'!C:G,5,0) -> GEMÜ | CR10: =COUNTIF(CL10:CP10,CP10) -> 2
B11: Descarte BV fundo | C11: DN-40 | D11: GEMÜ | E11: =VLOOKUP(B11,'FTD02'!C:E,1,0) -> Descarte BV fundo | F11: =VLOOKUP(B11,'FTD02'!C:E,3,0) -> DN-40 | G11: =VLOOKUP(B11,'FTD02'!C:G,5,0) -> GEMÜ | H11: =VLOOKUP(B11,'FTD03'!C:E,1,0) -> Descarte BV fundo | I11: =VLOOKUP(B11,'FTD03'!C:E,3,0) -> DN-40 | J11: =VLOOKUP(B11,'FTD03'!C:G,5,0) -> GEMÜ | K11: =VLOOKUP(B11,'FTD04'!C:E,1,0) -> Descarte BV fundo | L11: =VLOOKUP(B11,'FTD04'!C:E,3,0) -> DN-40 | M11: =VLOOKUP(B11,'FTD04'!C:G,5,0) -> GEMÜ | N11: =VLOOKUP(B11,'FTD05'!C:E,1,0) -> Descarte BV fundo | O11: =VLOOKUP(B11,'FTD05'!C:E,3,0) -> DN-40 | P11: =VLOOKUP(B11,'FTD05'!C:G,5,0) -> GEMÜ | Q11: =VLOOKUP(B11,'FTD06'!C:E,1,0) -> Descarte BV fundo | R11: =VLOOKUP(B11,'FTD06'!C:E,3,0) -> DN-40 | S11: =VLOOKUP(B11,'FTD06'!C:G,5,0) -> GEMÜ | T11: =VLOOKUP(B11,'FTD07'!C:E,1,0) -> Descarte BV fundo | U11: =VLOOKUP(B11,'FTD07'!C:E,3,0) -> DN-40 | V11: =VLOOKUP(B11,'FTD07'!C:G,5,0) -> GEMÜ | W11: =VLOOKUP(B11,'FTD08'!C:E,1,0) -> Descarte BV fundo | X11: =VLOOKUP(B11,'FTD08'!C:E,3,0) -> DN-40 | Y11: =VLOOKUP(B11,'FTD08'!C:G,5,0) -> GEMÜ | Z11: =VLOOKUP(B11,'FTD09'!C:E,1,0) -> Descarte BV fundo | AA11: =VLOOKUP(B11,'FTD09'!C:E,3,0) -> DN-40 | AB11: =VLOOKUP(B11,'FTD09'!C:G,5,0) -> GEMÜ | AC11: =VLOOKUP(B11,'FTD10'!C:E,1,0) -> Descarte BV fundo | AD11: =VLOOKUP(B11,'FTD10'!C:E,3,0) -> DN-40 | AE11: =VLOOKUP(B11,'FTD10'!C:G,5,0) -> GEMÜ | AF11: =VLOOKUP(B11,'FTD11'!C:E,1,0) -> Descarte BV fundo | AG11: =VLOOKUP(B11,'FTD11'!C:E,3,0) -> DN-40 | AH11: =VLOOKUP(B11,'FTD11'!C:G,5,0) -> GEMÜ | AI11: =VLOOKUP(B11,'FTD12'!C:E,1,0) -> Descarte BV fundo | AJ11: =VLOOKUP(B11,'FTD12'!C:E,3,0) -> DN-40 | AK11: =VLOOKUP(B11,'FTD12'!C:G,5,0) -> GEMÜ | AL11: =COUNTIF(E11:AJ11,AJ11) -> 11 | AN11: Inferior | AO11: Válvula injetora de vapor | AP11: DN-40 | AQ11: XV-09.22 | AR11: =VLOOKUP(AN11,'PGD02'!A:E,1,0) -> Inferior | AS11: =VLOOKUP(AO11,'PGD02'!C:E,1,0) -> Válvula injetora de vapor | AT11: =VLOOKUP(AO11,'PGD02'!C:E,3,0) -> DN-40 | AU11: =VLOOKUP(AO11,'PGD02'!C:G,5,0) -> GEMÜ | AV11: =VLOOKUP(AN11,'PGD03'!A:E,1,0) -> Inferior | AW11: =VLOOKUP(AO11,'PGD03'!C:E,1,0) -> Válvula injetora de vapor | AX11: =VLOOKUP(AO11,'PGD03'!C:E,3,0) -> DN-40 | AY11: =VLOOKUP(AO11,'PGD03'!C:G,5,0) -> GEMÜ | AZ11: =VLOOKUP(AN11,'PGD04'!A:E,1,0) -> Inferior | BA11: =VLOOKUP(AO11,'PGD03'!C:E,1,0) -> Válvula injetora de vapor | BB11: =VLOOKUP(AO11,'PGD04'!C:E,3,0) -> DN-40 | BC11: =VLOOKUP(AO11,'PGD04'!C:G,5,0) -> GEMÜ | BD11: =VLOOKUP(AN11,'PGD05'!A:E,1,0) -> Inferior | BE11: =VLOOKUP(AO11,'PGD05'!C:E,1,0) -> Válvula injetora de vapor | BF11: =VLOOKUP(AO11,'PGD05'!C:E,3,0) -> DN-40 | BG11: =VLOOKUP(AO11,'PGD05'!C:G,5,0) -> GEMÜ | BH11: =VLOOKUP(AN11,'PGD06'!A:E,1,0) -> Inferior | BI11: =VLOOKUP(AO11,'PGD06'!C:E,1,0) -> Válvula injetora de vapor | BJ11: =VLOOKUP(AO11,'PGD06'!C:E,3,0) -> DN-40 | BK11: =VLOOKUP(AO11,'PGD06'!C:G,5,0) -> GEMÜ | BL11: =VLOOKUP(AN11,'PGD07'!A:E,1,0) -> Inferior | BM11: =VLOOKUP(AO11,'PGD07'!C:E,1,0) -> Válvula injetora de vapor | BN11: =VLOOKUP(AO11,'PGD07'!C:E,3,0) -> DN-40 | BO11: =VLOOKUP(AO11,'PGD07'!C:G,5,0) -> GEMÜ | BP11: =VLOOKUP(AN11,'PGD08'!A:E,1,0) -> Inferior | BQ11: =VLOOKUP(AO11,'PGD08'!C:E,1,0) -> Válvula injetora de vapor | BR11: =VLOOKUP(AO11,'PGD08'!C:E,3,0) -> DN-40 | BS11: =VLOOKUP(AO11,'PGD08'!C:G,5,0) -> GEMÜ | BT11: =VLOOKUP(AN11,'PGD09'!A:E,1,0) -> Inferior | BU11: =VLOOKUP(AO11,'PGD09'!C:E,1,0) -> Válvula injetora de vapor | BV11: =VLOOKUP(AO11,'PGD09'!C:E,3,0) -> DN-40 | BW11: =VLOOKUP(AO11,'PGD09'!C:G,5,0) -> GEMÜ | BX11: =VLOOKUP(AN11,'PGD10'!A:E,1,0) -> Inferior | BY11: =VLOOKUP(AO11,'PGD10'!C:E,1,0) -> Válvula injetora de vapor | BZ11: =VLOOKUP(AO11,'PGD10'!C:E,3,0) -> DN-40 | CA11: =VLOOKUP(AO11,'PGD10'!C:G,5,0) -> GEMÜ | CB11: =VLOOKUP(AN11,'PGD11'!A:E,1,0) -> Inferior | CC11: =VLOOKUP(AO11,'PGD11'!C:E,1,0) -> Válvula injetora de vapor | CD11: =VLOOKUP(AO11,'PGD11'!C:E,3,0) -> DN-40 | CE11: =VLOOKUP(AO11,'PGD11'!C:G,5,0) -> GEMÜ | CF11: =VLOOKUP(AN11,'PGD12'!A:E,1,0) -> Inferior | CG11: =VLOOKUP(AO11,'PGD12'!C:E,1,0) -> Válvula injetora de vapor | CH11: =VLOOKUP(AO11,'PGD12'!C:E,3,0) -> DN-40 | CI11: =VLOOKUP(AO11,'PGD12'!C:G,5,0) -> GEMÜ | CJ11: =COUNTIF(AS11:CH11,CH11) -> 11 | CL11: Bloco 2 vias fundo - vapor | CM11: DN-8 | CN11: ZDL | CO11: =VLOOKUP(CL11,'BLD03'!C:E,1,0) -> bloco 2 vias fundo - vapor | CP11: =VLOOKUP(CL11,'BLD03'!C:E,3,0) -> DN-8 | CQ11: =VLOOKUP(CL11,'BLD02'!C:G,5,0) -> ZDL | CR11: =COUNTIF(CL11:CP11,CP11) -> 2
B12: Entrada de vapor linha de ar pós filtro absoluto | C12: DN-80 | D12: GEMÜ | E12: =VLOOKUP(B12,'FTD02'!C:E,1,0) -> Entrada de vapor linha de ar pós filtro absoluto | F12: =VLOOKUP(B12,'FTD02'!C:E,3,0) -> DN-40 | G12: =VLOOKUP(B12,'FTD02'!C:G,5,0) -> GEMÜ | H12: =VLOOKUP(B12,'FTD03'!C:E,1,0) -> Entrada de vapor linha de ar pós filtro absoluto | I12: =VLOOKUP(B12,'FTD03'!C:E,3,0) -> DN-40 | J12: =VLOOKUP(B12,'FTD03'!C:G,5,0) -> GEMÜ | K12: =VLOOKUP(B12,'FTD04'!C:E,1,0) -> Entrada de vapor linha de ar pós filtro absoluto | L12: =VLOOKUP(B12,'FTD04'!C:E,3,0) -> DN-40 | M12: =VLOOKUP(B12,'FTD04'!C:G,5,0) -> GEMÜ | N12: =VLOOKUP(B12,'FTD05'!C:E,1,0) -> Entrada de vapor linha de ar pós filtro absoluto | O12: =VLOOKUP(B12,'FTD05'!C:E,3,0) -> DN-40 | P12: =VLOOKUP(B12,'FTD05'!C:G,5,0) -> GEMÜ | Q12: =VLOOKUP(B12,'FTD06'!C:E,1,0) -> Entrada de vapor linha de ar pós filtro absoluto | R12: =VLOOKUP(B12,'FTD06'!C:E,3,0) -> DN-40 | S12: =VLOOKUP(B12,'FTD06'!C:G,5,0) -> GEMÜ | T12: =VLOOKUP(B12,'FTD07'!C:E,1,0) -> Entrada de vapor linha de ar pós filtro absoluto | U12: =VLOOKUP(B12,'FTD07'!C:E,3,0) -> DN-40 | V12: =VLOOKUP(B12,'FTD07'!C:G,5,0) -> GEMÜ | W12: =VLOOKUP(B12,'FTD08'!C:E,1,0) -> Entrada de vapor linha de ar pós filtro absoluto | X12: =VLOOKUP(B12,'FTD08'!C:E,3,0) -> DN-40 | Y12: =VLOOKUP(B12,'FTD08'!C:G,5,0) -> GEMÜ | Z12: =VLOOKUP(B12,'FTD09'!C:E,1,0) -> Entrada de vapor linha de ar pós filtro absoluto | AA12: =VLOOKUP(B12,'FTD09'!C:E,3,0) -> DN-40 | AB12: =VLOOKUP(B12,'FTD09'!C:G,5,0) -> GEMÜ | AC12: =VLOOKUP(B12,'FTD10'!C:E,1,0) -> Entrada de vapor linha de ar pós filtro absoluto | AD12: =VLOOKUP(B12,'FTD10'!C:E,3,0) -> DN-40 | AE12: =VLOOKUP(B12,'FTD10'!C:G,5,0) -> GEMÜ | AF12: =VLOOKUP(B12,'FTD11'!C:E,1,0) -> Entrada de vapor linha de ar pós filtro absoluto | AG12: =VLOOKUP(B12,'FTD11'!C:E,3,0) -> DN-40 | AH12: =VLOOKUP(B12,'FTD11'!C:G,5,0) -> GEMÜ | AI12: =VLOOKUP(B12,'FTD12'!C:E,1,0) -> Entrada de vapor linha de ar pós filtro absoluto | AJ12: =VLOOKUP(B12,'FTD12'!C:E,3,0) -> DN-40 | AK12: =VLOOKUP(B12,'FTD12'!C:G,5,0) -> GEMÜ | AL12: =COUNTIF(E12:AJ12,AJ12) -> 11 | AN12: Inferior | AO12: Linha vapor fundo esterilização | AP12: DN-8 | AQ12: BV-09.25-3 B | AR12: =VLOOKUP(AN12,'PGD02'!A:E,1,0) -> Inferior | AS12: =VLOOKUP(AO12,'PGD02'!C:E,1,0) -> Linha vapor fundo esterilização | AT12: =VLOOKUP(AO12,'PGD02'!C:E,3,0) -> DN-8 | AU12: =VLOOKUP(AO12,'PGD02'!C:G,5,0) -> GEMÜ | AV12: =VLOOKUP(AN12,'PGD03'!A:E,1,0) -> Inferior | AW12: =VLOOKUP(AO12,'PGD03'!C:E,1,0) -> Linha vapor fundo esterilização | AX12: =VLOOKUP(AO12,'PGD03'!C:E,3,0) -> DN-8 | AY12: =VLOOKUP(AO12,'PGD03'!C:G,5,0) -> ZDL | AZ12: =VLOOKUP(AN12,'PGD04'!A:E,1,0) -> Inferior | BA12: =VLOOKUP(AO12,'PGD03'!C:E,1,0) -> Linha vapor fundo esterilização | BB12: =VLOOKUP(AO12,'PGD04'!C:E,3,0) -> DN-8 | BC12: =VLOOKUP(AO12,'PGD04'!C:G,5,0) -> ZDL | BD12: =VLOOKUP(AN12,'PGD05'!A:E,1,0) -> Inferior | BE12: =VLOOKUP(AO12,'PGD05'!C:E,1,0) -> Linha vapor fundo esterilização | BF12: =VLOOKUP(AO12,'PGD05'!C:E,3,0) -> DN-8 | BG12: =VLOOKUP(AO12,'PGD05'!C:G,5,0) -> ZDL | BH12: =VLOOKUP(AN12,'PGD06'!A:E,1,0) -> Inferior | BI12: =VLOOKUP(AO12,'PGD06'!C:E,1,0) -> Linha vapor fundo esterilização | BJ12: =VLOOKUP(AO12,'PGD06'!C:E,3,0) -> DN-8 | BK12: =VLOOKUP(AO12,'PGD06'!C:G,5,0) -> ZDL | BL12: =VLOOKUP(AN12,'PGD07'!A:E,1,0) -> Inferior | BM12: =VLOOKUP(AO12,'PGD07'!C:E,1,0) -> Linha vapor fundo esterilização | BN12: =VLOOKUP(AO12,'PGD07'!C:E,3,0) -> DN-8 | BO12: =VLOOKUP(AO12,'PGD07'!C:G,5,0) -> ZDL | BP12: =VLOOKUP(AN12,'PGD08'!A:E,1,0) -> Inferior | BQ12: =VLOOKUP(AO12,'PGD08'!C:E,1,0) -> Linha vapor fundo esterilização | BR12: =VLOOKUP(AO12,'PGD08'!C:E,3,0) -> DN-8 | BS12: =VLOOKUP(AO12,'PGD08'!C:G,5,0) -> ZDL | BT12: =VLOOKUP(AN12,'PGD09'!A:E,1,0) -> Inferior | BU12: =VLOOKUP(AO12,'PGD09'!C:E,1,0) -> Linha vapor fundo esterilização | BV12: =VLOOKUP(AO12,'PGD09'!C:E,3,0) -> DN-8 | BW12: =VLOOKUP(AO12,'PGD09'!C:G,5,0) -> ZDL | BX12: =VLOOKUP(AN12,'PGD10'!A:E,1,0) -> Inferior | BY12: =VLOOKUP(AO12,'PGD10'!C:E,1,0) -> Linha vapor fundo esterilização | BZ12: =VLOOKUP(AO12,'PGD10'!C:E,3,0) -> DN-8 | CA12: =VLOOKUP(AO12,'PGD10'!C:G,5,0) -> ZDL | CB12: =VLOOKUP(AN12,'PGD11'!A:E,1,0) -> Inferior | CC12: =VLOOKUP(AO12,'PGD11'!C:E,1,0) -> Linha vapor fundo esterilização | CD12: =VLOOKUP(AO12,'PGD11'!C:E,3,0) -> DN-8 | CE12: =VLOOKUP(AO12,'PGD11'!C:G,5,0) -> ZDL | CF12: =VLOOKUP(AN12,'PGD12'!A:E,1,0) -> Inferior | CG12: =VLOOKUP(AO12,'PGD12'!C:E,1,0) -> Linha vapor fundo esterilização | CH12: =VLOOKUP(AO12,'PGD12'!C:E,3,0) -> DN-8 | CI12: =VLOOKUP(AO12,'PGD12'!C:G,5,0) -> GEMÜ | CJ12: =COUNTIF(AS12:CH12,CH12) -> 11 | CL12: Entrada de água fria | CM12: DN-50 | CN12: GEMÜ | CO12: =VLOOKUP(CL12,'BLD03'!C:E,1,0) -> Entrada de água fria | CP12: =VLOOKUP(CL12,'BLD03'!C:E,3,0) -> DN-50 | CQ12: =VLOOKUP(CL12,'BLD02'!C:G,5,0) -> GEMÜ | CR12: =COUNTIF(CL12:CP12,CP12) -> 2
B13: Válvula injetora de vapor | C13: DN-80 | D13: GEMÜ | E13: =VLOOKUP(B13,'FTD02'!C:E,1,0) -> Válvula injetora de vapor | F13: =VLOOKUP(B13,'FTD02'!C:E,3,0) -> DN-80 | G13: =VLOOKUP(B13,'FTD02'!C:G,5,0) -> GEMÜ | H13: =VLOOKUP(B13,'FTD03'!C:E,1,0) -> Válvula injetora de vapor | I13: =VLOOKUP(B13,'FTD03'!C:E,3,0) -> DN-80 | J13: =VLOOKUP(B13,'FTD03'!C:G,5,0) -> GEMÜ | K13: =VLOOKUP(B13,'FTD04'!C:E,1,0) -> Válvula injetora de vapor | L13: =VLOOKUP(B13,'FTD04'!C:E,3,0) -> DN-80 | M13: =VLOOKUP(B13,'FTD04'!C:G,5,0) -> GEMÜ | N13: =VLOOKUP(B13,'FTD05'!C:E,1,0) -> Válvula injetora de vapor | O13: =VLOOKUP(B13,'FTD05'!C:E,3,0) -> DN-80 | P13: =VLOOKUP(B13,'FTD05'!C:G,5,0) -> GEMÜ | Q13: =VLOOKUP(B13,'FTD06'!C:E,1,0) -> Válvula injetora de vapor | R13: =VLOOKUP(B13,'FTD06'!C:E,3,0) -> DN-80 | S13: =VLOOKUP(B13,'FTD06'!C:G,5,0) -> GEMÜ | T13: =VLOOKUP(B13,'FTD07'!C:E,1,0) -> Válvula injetora de vapor | U13: =VLOOKUP(B13,'FTD07'!C:E,3,0) -> DN-80 | V13: =VLOOKUP(B13,'FTD07'!C:G,5,0) -> GEMÜ | W13: =VLOOKUP(B13,'FTD08'!C:E,1,0) -> Válvula injetora de vapor | X13: =VLOOKUP(B13,'FTD08'!C:E,3,0) -> DN-80 | Y13: =VLOOKUP(B13,'FTD08'!C:G,5,0) -> GEMÜ | Z13: =VLOOKUP(B13,'FTD09'!C:E,1,0) -> Válvula injetora de vapor | AA13: =VLOOKUP(B13,'FTD09'!C:E,3,0) -> DN-80 | AB13: =VLOOKUP(B13,'FTD09'!C:G,5,0) -> GEMÜ | AC13: =VLOOKUP(B13,'FTD10'!C:E,1,0) -> Válvula injetora de vapor | AD13: =VLOOKUP(B13,'FTD10'!C:E,3,0) -> DN-80 | AE13: =VLOOKUP(B13,'FTD10'!C:G,5,0) -> GEMÜ | AF13: =VLOOKUP(B13,'FTD11'!C:E,1,0) -> Válvula injetora de vapor | AG13: =VLOOKUP(B13,'FTD11'!C:E,3,0) -> DN-80 | AH13: =VLOOKUP(B13,'FTD11'!C:G,5,0) -> GEMÜ | AI13: =VLOOKUP(B13,'FTD12'!C:E,1,0) -> Válvula injetora de vapor | AJ13: =VLOOKUP(B13,'FTD12'!C:E,3,0) -> DN-80 | AK13: =VLOOKUP(B13,'FTD12'!C:G,5,0) -> GEMÜ | AL13: =COUNTIF(E13:AJ13,AJ13) -> 11 | AN13: Inferior | AO13: Trasnferência BV | AP13: DN-40 | AQ13: BV - 09.25-1 | AR13: =VLOOKUP(AN13,'PGD02'!A:E,1,0) -> Inferior | AS13: =VLOOKUP(AO13,'PGD02'!C:E,1,0) -> Trasnferência BV | AT13: =VLOOKUP(AO13,'PGD02'!C:E,3,0) -> DN-40 | AU13: =VLOOKUP(AO13,'PGD02'!C:G,5,0) -> GEMÜ | AV13: =VLOOKUP(AN13,'PGD03'!A:E,1,0) -> Inferior | AW13: =VLOOKUP(AO13,'PGD03'!C:E,1,0) -> Trasnferência BV | AX13: =VLOOKUP(AO13,'PGD03'!C:E,3,0) -> DN-40 | AY13: =VLOOKUP(AO13,'PGD03'!C:G,5,0) -> GEMÜ | AZ13: =VLOOKUP(AN13,'PGD04'!A:E,1,0) -> Inferior | BA13: =VLOOKUP(AO13,'PGD03'!C:E,1,0) -> Trasnferência BV | BB13: =VLOOKUP(AO13,'PGD04'!C:E,3,0) -> DN-40 | BC13: =VLOOKUP(AO13,'PGD04'!C:G,5,0) -> GEMÜ | BD13: =VLOOKUP(AN13,'PGD05'!A:E,1,0) -> Inferior | BE13: =VLOOKUP(AO13,'PGD05'!C:E,1,0) -> Trasnferência BV | BF13: =VLOOKUP(AO13,'PGD05'!C:E,3,0) -> DN-40 | BG13: =VLOOKUP(AO13,'PGD05'!C:G,5,0) -> GEMÜ | BH13: =VLOOKUP(AN13,'PGD06'!A:E,1,0) -> Inferior | BI13: =VLOOKUP(AO13,'PGD06'!C:E,1,0) -> Trasnferência BV | BJ13: =VLOOKUP(AO13,'PGD06'!C:E,3,0) -> DN-40 | BK13: =VLOOKUP(AO13,'PGD06'!C:G,5,0) -> GEMÜ | BL13: =VLOOKUP(AN13,'PGD07'!A:E,1,0) -> Inferior | BM13: =VLOOKUP(AO13,'PGD07'!C:E,1,0) -> Trasnferência BV | BN13: =VLOOKUP(AO13,'PGD07'!C:E,3,0) -> DN-40 | BO13: =VLOOKUP(AO13,'PGD07'!C:G,5,0) -> GEMÜ | BP13: =VLOOKUP(AN13,'PGD08'!A:E,1,0) -> Inferior | BQ13: =VLOOKUP(AO13,'PGD08'!C:E,1,0) -> Trasnferência BV | BR13: =VLOOKUP(AO13,'PGD08'!C:E,3,0) -> DN-40 | BS13: =VLOOKUP(AO13,'PGD08'!C:G,5,0) -> ZDL | BT13: =VLOOKUP(AN13,'PGD09'!A:E,1,0) -> Inferior | BU13: =VLOOKUP(AO13,'PGD09'!C:E,1,0) -> Trasnferência BV | BV13: =VLOOKUP(AO13,'PGD09'!C:E,3,0) -> DN-40 | BW13: =VLOOKUP(AO13,'PGD09'!C:G,5,0) -> GEMÜ | BX13: =VLOOKUP(AN13,'PGD10'!A:E,1,0) -> Inferior | BY13: =VLOOKUP(AO13,'PGD10'!C:E,1,0) -> Trasnferência BV | BZ13: =VLOOKUP(AO13,'PGD10'!C:E,3,0) -> DN-40 | CA13: =VLOOKUP(AO13,'PGD10'!C:G,5,0) -> GEMÜ | CB13: =VLOOKUP(AN13,'PGD11'!A:E,1,0) -> Inferior | CC13: =VLOOKUP(AO13,'PGD11'!C:E,1,0) -> Trasnferência BV | CD13: =VLOOKUP(AO13,'PGD11'!C:E,3,0) -> DN-40 | CE13: =VLOOKUP(AO13,'PGD11'!C:G,5,0) -> GEMÜ | CF13: =VLOOKUP(AN13,'PGD12'!A:E,1,0) -> Inferior | CG13: =VLOOKUP(AO13,'PGD12'!C:E,1,0) -> Trasnferência BV | CH13: =VLOOKUP(AO13,'PGD12'!C:E,3,0) -> DN-40 | CI13: =VLOOKUP(AO13,'PGD12'!C:G,5,0) -> GEMÜ | CJ13: =COUNTIF(AS13:CH13,CH13) -> 11 | CL13: Entrada bloco BV água quente | CM13: DN-50 | CN13: GEMÜ | CO13: =VLOOKUP(CL13,'BLD03'!C:E,1,0) -> Entrada bloco BV água quente | CP13: =VLOOKUP(CL13,'BLD03'!C:E,3,0) -> DN-50 | CQ13: =VLOOKUP(CL13,'BLD02'!C:G,5,0) -> GEMÜ | CR13: =COUNTIF(CL13:CP13,CP13) -> 2
B14: Trasnferência BV fundo | C14: DN-40 | D14: GEMÜ | E14: =VLOOKUP(B14,'FTD02'!C:E,1,0) -> Trasnferência BV fundo | F14: =VLOOKUP(B14,'FTD02'!C:E,3,0) -> DN-40 | G14: =VLOOKUP(B14,'FTD02'!C:G,5,0) -> GEMÜ | H14: =VLOOKUP(B14,'FTD03'!C:E,1,0) -> Trasnferência BV fundo | I14: =VLOOKUP(B14,'FTD03'!C:E,3,0) -> DN-40 | J14: =VLOOKUP(B14,'FTD03'!C:G,5,0) -> GEMÜ | K14: =VLOOKUP(B14,'FTD04'!C:E,1,0) -> Trasnferência BV fundo | L14: =VLOOKUP(B14,'FTD04'!C:E,3,0) -> DN-40 | M14: =VLOOKUP(B14,'FTD04'!C:G,5,0) -> GEMÜ | N14: =VLOOKUP(B14,'FTD05'!C:E,1,0) -> Trasnferência BV fundo | O14: =VLOOKUP(B14,'FTD05'!C:E,3,0) -> DN-40 | P14: =VLOOKUP(B14,'FTD05'!C:G,5,0) -> GEMÜ | Q14: =VLOOKUP(B14,'FTD06'!C:E,1,0) -> Trasnferência BV fundo | R14: =VLOOKUP(B14,'FTD06'!C:E,3,0) -> DN-40 | S14: =VLOOKUP(B14,'FTD06'!C:G,5,0) -> GEMÜ | T14: =VLOOKUP(B14,'FTD07'!C:E,1,0) -> Trasnferência BV fundo | U14: =VLOOKUP(B14,'FTD07'!C:E,3,0) -> DN-40 | V14: =VLOOKUP(B14,'FTD07'!C:G,5,0) -> GEMÜ | W14: =VLOOKUP(B14,'FTD08'!C:E,1,0) -> Trasnferência BV fundo | X14: =VLOOKUP(B14,'FTD08'!C:E,3,0) -> DN-40 | Y14: =VLOOKUP(B14,'FTD08'!C:G,5,0) -> GEMÜ | Z14: =VLOOKUP(B14,'FTD09'!C:E,1,0) -> Trasnferência BV fundo | AA14: =VLOOKUP(B14,'FTD09'!C:E,3,0) -> DN-40 | AB14: =VLOOKUP(B14,'FTD09'!C:G,5,0) -> GEMÜ | AC14: =VLOOKUP(B14,'FTD10'!C:E,1,0) -> Trasnferência BV fundo | AD14: =VLOOKUP(B14,'FTD10'!C:E,3,0) -> DN-40 | AE14: =VLOOKUP(B14,'FTD10'!C:G,5,0) -> GEMÜ | AF14: =VLOOKUP(B14,'FTD11'!C:E,1,0) -> Trasnferência BV fundo | AG14: =VLOOKUP(B14,'FTD11'!C:E,3,0) -> DN-40 | AH14: =VLOOKUP(B14,'FTD11'!C:G,5,0) -> GEMÜ | AI14: =VLOOKUP(B14,'FTD12'!C:E,1,0) -> Trasnferência BV fundo | AJ14: =VLOOKUP(B14,'FTD12'!C:E,3,0) -> DN-40 | AK14: =VLOOKUP(B14,'FTD12'!C:G,5,0) -> GEMÜ | AL14: =COUNTIF(E14:AJ14,AJ14) -> 11 | AN14: Superior | AO14: Dreno BV alimentação carbono | AP14: DN-25 | AQ14: BV - 09.07-3 | AR14: =VLOOKUP(AN14,'PGD02'!A:E,1,0) -> Superior | AS14: =VLOOKUP(AO14,'PGD02'!C:E,1,0) -> Dreno BV alimentação carbono | AT14: =VLOOKUP(AO14,'PGD02'!C:E,3,0) -> DN-25 | AU14: =VLOOKUP(AO14,'PGD02'!C:G,5,0) -> GEMÜ | AV14: =VLOOKUP(AN14,'PGD03'!A:E,1,0) -> Superior | AW14: =VLOOKUP(AO14,'PGD03'!C:E,1,0) -> Dreno BV alimentação carbono | AX14: =VLOOKUP(AO14,'PGD03'!C:E,3,0) -> DN-25 | AY14: =VLOOKUP(AO14,'PGD03'!C:G,5,0) -> GEMÜ | AZ14: =VLOOKUP(AN14,'PGD04'!A:E,1,0) -> Superior | BA14: =VLOOKUP(AO14,'PGD03'!C:E,1,0) -> Dreno BV alimentação carbono | BB14: =VLOOKUP(AO14,'PGD04'!C:E,3,0) -> DN-25 | BC14: =VLOOKUP(AO14,'PGD04'!C:G,5,0) -> GEMÜ | BD14: =VLOOKUP(AN14,'PGD05'!A:E,1,0) -> Superior | BE14: =VLOOKUP(AO14,'PGD05'!C:E,1,0) -> Dreno BV alimentação carbono | BF14: =VLOOKUP(AO14,'PGD05'!C:E,3,0) -> DN-25 | BG14: =VLOOKUP(AO14,'PGD05'!C:G,5,0) -> GEMÜ | BH14: =VLOOKUP(AN14,'PGD06'!A:E,1,0) -> Superior | BI14: =VLOOKUP(AO14,'PGD06'!C:E,1,0) -> Dreno BV alimentação carbono | BJ14: =VLOOKUP(AO14,'PGD06'!C:E,3,0) -> DN-25 | BK14: =VLOOKUP(AO14,'PGD06'!C:G,5,0) -> GEMÜ | BL14: =VLOOKUP(AN14,'PGD07'!A:E,1,0) -> Superior | BM14: =VLOOKUP(AO14,'PGD07'!C:E,1,0) -> Dreno BV alimentação carbono | BN14: =VLOOKUP(AO14,'PGD07'!C:E,3,0) -> DN-25 | BO14: =VLOOKUP(AO14,'PGD07'!C:G,5,0) -> GEMÜ | BP14: =VLOOKUP(AN14,'PGD08'!A:E,1,0) -> Superior | BQ14: =VLOOKUP(AO14,'PGD08'!C:E,1,0) -> Dreno BV alimentação carbono | BR14: =VLOOKUP(AO14,'PGD08'!C:E,3,0) -> DN-25 | BS14: =VLOOKUP(AO14,'PGD08'!C:G,5,0) -> GEMÜ | BT14: =VLOOKUP(AN14,'PGD09'!A:E,1,0) -> Superior | BU14: =VLOOKUP(AO14,'PGD09'!C:E,1,0) -> Dreno BV alimentação carbono | BV14: =VLOOKUP(AO14,'PGD09'!C:E,3,0) -> DN-25 | BW14: =VLOOKUP(AO14,'PGD09'!C:G,5,0) -> GEMÜ | BX14: =VLOOKUP(AN14,'PGD10'!A:E,1,0) -> Superior | BY14: =VLOOKUP(AO14,'PGD10'!C:E,1,0) -> Dreno BV alimentação carbono | BZ14: =VLOOKUP(AO14,'PGD10'!C:E,3,0) -> DN-25 | CA14: =VLOOKUP(AO14,'PGD10'!C:G,5,0) -> GEMÜ | CB14: =VLOOKUP(AN14,'PGD11'!A:E,1,0) -> Superior | CC14: =VLOOKUP(AO14,'PGD11'!C:E,1,0) -> Dreno BV alimentação carbono | CD14: =VLOOKUP(AO14,'PGD11'!C:E,3,0) -> DN-25 | CE14: =VLOOKUP(AO14,'PGD11'!C:G,5,0) -> GEMÜ | CF14: =VLOOKUP(AN14,'PGD12'!A:E,1,0) -> Superior | CG14: =VLOOKUP(AO14,'PGD12'!C:E,1,0) -> Dreno BV alimentação carbono | CH14: =VLOOKUP(AO14,'PGD12'!C:E,3,0) -> DN-25 | CI14: =VLOOKUP(AO14,'PGD12'!C:G,5,0) -> GEMÜ | CJ14: =COUNTIF(AS14:CH14,CH14) -> 11 | CL14: Entrada blender água quente | CM14: DN-50 | CN14: GEMÜ | CO14: =VLOOKUP(CL14,'BLD03'!C:E,1,0) -> Entrada blender água quente | CP14: =VLOOKUP(CL14,'BLD03'!C:E,3,0) -> DN-50 | CQ14: =VLOOKUP(CL14,'BLD02'!C:G,5,0) -> GEMÜ | CR14: =COUNTIF(CL14:CP14,CP14) -> 2
